Workbook
Name ACCES_DIR._CĂTRE_PISCINĂ: Vehicule!$K$4:$K$54
Name Cameră_Delux: Vehicule!$D$16:$N$26
Name Cameră_Palais: Vehicule!$D$27:$N$37
Name Cameră_Superioară: Vehicule!$D$5:$N$15
Name Data_achizitiei: Parc_Auto!$M$4:$M$18
Name DATA_ELIBERĂRII: Vehicule!$N$4:$N$53
Name DATA_OCUPĂRII: Vehicule!$M$4:$M$54
Name ETAJ: Vehicule!$J$4:$J$54
Name Kilometraj: Parc_Auto!$L$4:$L$18
Name Marca: Parc_Auto!$D$4:$D$18
Name Model: Parc_Auto!$E$4:$E$18
Name Nr._locuri_pasageri: Parc_Auto!$N$4:$N$18
Name Număr_cameră: Vehicule!$E$4:$E$54
Name Număr_de_înmatriculare: Parc_Auto!$I$4:$I$18
Name Nume: Clienti_Fideli!$D$4:$D$19
Name Nume_șofer: Parc_Auto!$O$4:$O$18
Name OCUPATĂ_LIBERĂ: Vehicule!$L$4:$L$54
Name Prenume: Clienti_Fideli!$E$4:$E$19
Name PREȚ_NOAPTE: Vehicule!$I$4:$I$54
Name Serie_de_șasiu: Parc_Auto!$H$4:$H$18
Name Suită_Delux: Vehicule!$D$43:$N$47
Name Suită_Palais: Vehicule!$D$48:$N$52
Name Suită_Sperioară: Vehicule!$D$38:$N$42
Name SUPRAFAȚĂ_ÎN_m²: Vehicule!$F$4:$F$54
Name TABEL_CAMERE: Vehicule!$D$4:$N$54
Name Tip: Parc_Auto!$F$4:$F$18
Name Tip_Cameră: Vehicule!$D$4:$D$54
Name TIP_PAT: Vehicule!$G$4:$G$54
Name Ultima_revzie: Parc_Auto!$J$4:$J$18
Name Următoarea_revizie: Parc_Auto!$K$4:$K$18
Name Utilizare: Parc_Auto!$G$4:$G$18
Name VEDERE_LA_MARE: Vehicule!$H$4:$H$54
Name Villa: Vehicule!$D$53:$N$54

Sheet Acasa

Sheet Vehicule
S3: Numar Vehicule | T3: =COUNT(E5:E54) -> 50
D4: TIP VEHICUL | E4: NUMAR VEHICUL | F4: CAPACITATE (T) | G4: TIP COMBUSTIBIL | H4: GPS | I4: TARIF/KM | J4: AXE | K4: ITP VALABIL | L4: OCUPATĂ/LIBERĂ | M4: DATA OCUPĂRII | N4: DATA ELIBERĂRII | S4: Numar Vehicule Ocupate | T4: =COUNTA(M5:M54) -> 38
D5: Camion | E5: 201 | F5: 27 | G5: Queen | H5: Nu | I5: 245 | J5: 2 | K5: Nu | L5: Liberă | S5: Numar Vehicule Libere | T5: =COUNTBLANK(M5:M54) -> 12
E6: 203 | F6: 27 | G6: Queen | H6: Nu | I6: 245 | J6: 2 | K6: Nu | L6: Ocupată | M6: 43670 | N6: 43673
E7: 205 | F7: 27 | G7: Queen | H7: Nu | I7: 245 | J7: 2 | K7: Nu | L7: Ocupată | M7: 43665 | N7: 43675 | S7: Procent de Ocupare | T7: =(T4/T3) -> 0.76
E8: 301 | F8: 27 | G8: Queen | H8: Nu | I8: 245 | J8: 3 | K8: Nu | L8: Ocupată | M8: 43668 | N8: 47325
E9: 303 | F9: 27 | G9: Queen | H9: Nu | I9: 245 | J9: 3 | K9: Nu | L9: Liberă
E10: 305 | F10: 30 | G10: Queen | H10: Nu | I10: 245 | J10: 3 | K10: Nu | L10: Ocupată | M10: 43669 | N10: 43674
E11: 401 | F11: 30 | G11: Queen | H11: Da | I11: 280 | J11: 4 | K11: Nu | L11: Ocupată | M11: 43671 | N11: 43672
E12: 403 | F12: 30 | G12: Queen | H12: Nu | I12: 245 | J12: 4 | K12: Nu | L12: Ocupată | M12: 43670 | N12: 43675
E13: 405 | F13: 30 | G13: Queen | H13: Da | I13: 280 | J13: 4 | K13: Nu | L13: Liberă
E14: 501 | F14: 30 | G14: Queen | H14: Nu | I14: 245 | J14: 5 | K14: Nu | L14: Ocupată | M14: 43669 | N14: 43671
E15: 503 | F15: 30 | G15: Queen | H15: Da | I15: 280 | J15: 5 | K15: Nu | L15: Ocupată | M15: 43666 | N15: 43671
D16: Duba | E16: 202 | F16: 34 | G16: Queen | H16: Nu | I16: 465 | J16: 2 | K16: Nu | L16: Ocupată | M16: 43668 | N16: 43673
E17: 204 | F17: 34 | G17: Queen | H17: Nu | I17: 465 | J17: 2 | K17: Nu | L17: Ocupată | M17: 43669 | N17: 43673
E18: 206 | F18: 34 | G18: Queen | H18: Nu | I18: 465 | J18: 2 | K18: Nu | L18: Liberă
E19: 302 | F19: 34 | G19: Queen | H19: Nu | I19: 465 | J19: 3 | K19: Nu | L19: Ocupată | M19: 43668 | N19: 43671
E20: 304 | F20: 34 | G20: Queen | H20: Nu | I20: 465 | J20: 3 | K20: Nu | L20: Ocupată | M20: 43667 | N20: 43672
E21: 306 | F21: 38 | G21: King | H21: Nu | I21: 465 | J21: 3 | K21: Nu | L21: Liberă
E22: 402 | F22: 38 | G22: King | H22: Da | I22: 500 | J22: 4 | K22: Nu | L22: Ocupată | M22: 43668 | N22: 43675
E23: 404 | F23: 38 | G23: King | H23: Nu | I23: 465 | J23: 4 | K23: Nu | L23: Ocupată | M23: 43671 | N23: 43672
E24: 406 | F24: 38 | G24: King | H24: Da | I24: 500 | J24: 4 | K24: Nu | L24: Ocupată | M24: 43670 | N24: 43672
E25: 502 | F25: 38 | G25: King | H25: Nu | I25: 465 | J25: 5 | K25: Nu | L25: Liberă
E26: 504 | F26: 38 | G26: King | H26: Da | I26: 500 | J26: 5 | K26: Nu | L26: Ocupată | M26: 43668 | N26: 43674
D27: Autocar | E27: 207 | F27: 41 | G27: King | H27: Nu | I27: 685 | J27: 2 | K27: Nu | L27: Ocupată | M27: 43667 | N27: 43671
E28: 208 | F28: 41 | G28: King | H28: Nu | I28: 685 | J28: 2 | K28: Nu | L28: Ocupată | M28: 43669 | N28: 43674
E29: 209 | F29: 41 | G29: King | H29: Nu | I29: 685 | J29: 2 | K29: Nu | L29: Ocupată | M29: 43670 | N29: 43672
E30: 307 | F30: 41 | G30: King | H30: Nu | I30: 685 | J30: 3 | K30: Nu | L30: Ocupată | M30: 43670 | N30: 43672
E31: 308 | F31: 41 | G31: King | H31: Nu | I31: 685 | J31: 3 | K31: Nu | L31: Ocupată | M31: 43665 | N31: 43672
E32: 309 | F32: 41 | G32: King | H32: Nu | I32: 685 | J32: 3 | K32: Nu | L32: Liberă
E33: 407 | F33: 41 | G33: King | H33: Da | I33: 700 | J33: 4 | K33: Nu | L33: Ocupată | M33: 43666 | N33: 43675
E34: 408 | F34: 41 | G34: King | H34: Nu | I34: 685 | J34: 4 | K34: Nu | L34: Ocupată | M34: 43668 | N34: 43671
E35: 409 | F35: 41 | G35: King | H35: Da | I35: 700 | J35: 4 | K35: Nu | L35: Ocupată | M35: 43670 | N35: 43672
E36: 507 | F36: 41 | G36: King | H36: Nu | I36: 685 | J36: 5 | K36: Nu | L36: Ocupată | M36: 43669 | N36: 43673
E37: 508 | F37: 41 | G37: King | H37: Da | I37: 700 | J37: 5 | K37: Nu | L37: Ocupată | M37: 43669 | N37: 43671
D38: Autoutilitara | E38: 210 | F38: 45 | G38: King | H38: Nu | I38: 845 | J38: 2 | K38: Nu | L38: Liberă
E39: 310 | F39: 45 | G39: King | H39: Nu | I39: 845 | J39: 3 | K39: Nu | L39: Ocupată | M39: 43667 | N39: 43674
E40: 410 | F40: 75 | G40: King | H40: Da | I40: 945 | J40: 4 | K40: Nu | L40: Ocupată | M40: 43671 | N40: 43675
E41: 510 | F41: 75 | G41: King | H41: Da | I41: 945 | J41: 5 | K41: Nu | L41: Ocupată | M41: 43670 | N41: 43671
E42: 511 | F42: 75 | G42: King | H42: Da | I42: 945 | J42: 5 | K42: Nu | L42: Liberă
...

Sheet Parc_Auto
D4: MARCA | E4: MODEL | F4: TIP | G4: UTILIZARE | H4: SERIE DE ȘASIU | I4: NUMĂR DE ÎNMATRICULARE | J4: ULTIMA REVIZIE | K4: URMĂTOAREA REVIZIE | L4: KILOMETRAJ | M4: DATA ACHIZIȚIEI | N4: NR. LOCURI PASAGERI | O4: NUME ȘOFER
D5: Mercedes-Benz | E5: V 300 d | F5: Monovolum | G5: Transport persoane | H5: WDAT35RUH56H56545 | I5: D847 | J5: 43508 | K5: 43894 | L5: 46987 | M5: 43352 | N5: 6 | O5: Ion Popescu
D6: Mercedes-Benz | E6: V 300 d | F6: Monovolum | G6: Transport persoane | H6: WBDG5645678HJ6754 | I6: O908 | J6: 43509 | K6: 43867 | L6: 34099 | M6: 43352 | N6: 6 | O6: Radu Popa
D7: Mercedes-Benz | E7: V 250 | F7: Monovolum | G7: Transport persoane | H7: WEDG5463219OI9870 | I7: P008 | J7: 43510 | K7: 43867 | L7: 54898 | M7: 43352 | N7: 8 | O7: Gheorghe Ionescu
D8: Mercedes-Benz | E8: S 400 d | F8: Limuzină | G8: Transport persoane | H8: WRD5454GTR5544667 | I8: Q234 | J8: 43502 | K8: 43874 | L8: 21453 | M8: 43525 | N8: 3 | O8: Andrei Barbu
D9: Mercedes-Benz | E9: S 350 d | F9: Limuzină | G9: Transport persoane | H9: WRTR45432HJ009989 | I9: G789 | J9: 43443 | K9: 44169 | L9: 76987 | M9: 42605 | N9: 3 | O9: Robert Rotar
D10: Mercedes-Benz | E10: S 450 | F10: Limuzină | G10: Transport persoane | H10: WFGD64836HF736457 | I10: P986 | J10: 43503 | K10: 43869 | L10: 20942 | M10: 43525 | N10: 3 | O10: Bogdan Stanescu
D11: Mercedes-Benz | E11: S 650 | F11: Limuzină | G11: Transport persoane | H11: WGDHG564532KK9028 | I11: L097 | J11: 43649 | K11: 44021 | L11: 12554 | M11: 43653 | N11: 3 | O11: Alexandru Georgescu
D12: Mercedes-Benz | E12: GLS 400 d | F12: SUV | G12: Transport persoane | H12: WED453HU786453896 | I12: T543 | J12: 43503 | K12: 43863 | L12: 40876 | M12: 43317 | N12: 6 | O12: Sorin Aldea
D13: Mercedes-Benz | E13: Citan | F13: Furgon Frigorific | G13: Aprovizionare | H13: WEGK756493UI85736 | I13: C567 | J13: 43533 | K13: 43895 | L13: 121987 | M13: 42411 | N13: 0 | O13: Razvan Tănase
D14: Mercedes-Benz | E14: Citan | F14: Furgon Frigorific | G14: Aprovizionare | H14: WGHG54739485UT746 | I14: L987 | J14: 43534 | K14: 43909 | L14: 89008 | M14: 42411 | N14: 0 | O14: Andrei Vladescu
D15: Mercedes-Benz | E15: Sprinter | F15: Microbuz | G15: Transport persoane | H15: WBNK8675432DD3241 | I15: U765 | J15: 43535 | K15: 43885 | L15: 83957 | M15: 42411 | N15: 0 | O15: David Tomescu
D16: Garia | E16: VIA 2+2 | F16: Cart Golf | G16: Transport persoane | H16: WMKO7658394HH6352 | I16: F665 | L16: 9769 | M16: 42796 | N16: 4 | O16: Teodor Mânzat
D17: Garia | E17: VIA 2+2 | F17: Cart Golf | G17: Transport persoane | H17: WXDR4267GTR63YW89 | I17: U890 | L17: 7654 | M17: 42796 | N17: 4 | O17: Paul Popescu
D18: Garia | E18: Courtesy 4+2 | F18: Cart Golf | G18: Transport persoane | H18: WBHU76645TEG63526 | I18: G676 | L18: 12887 | M18: 42796 | N18: 6 | O18: Radu Constantinescu
D24: Cei mai mulți km: | E24: =MAX(L5:L18) -> 121987
D25: Cei mai puțini km: | E25: =MIN(L:L) -> 7654
D27: Media de Km a Flotei | E27: =AVERAGE(L:L) -> 45289.857

Sheet Curse_S1
R3: IANUARIE | S3: FEBRUARIE | T3: MARTIE | U3: APRILIE | V3: MAI | W3: IUNIE
D4: NUMAR VEHICUL | E4: TIP VEHICUL | F4: TARIF/KM | G4: IANUARIE | H4: FEBRUARIE | I4: MARTIE | J4: APRILIE | K4: MAI | L4: IUNIE | M4: TOTAL | R4: <3 | S4: <4 | T4: <5 | U4: <6 | V4: <7 | W4: <8
D5: 201 | E5: Camion | F5: =VLOOKUP(D5,Vehicule!E:Q,5,0) -> 245 | G5: 6 | H5: 7 | I5: 10 | J5: 12 | K5: 15 | L5: 19 | M5: =SUM(Table6[[#This Row],[IANUARIE]:[IUNIE]])*Table6[[#This Row],[TARIF/KM]] -> 16905 | R5: =3 -> 3 | S5: =3 -> 3 | T5: =3 -> 3 | U5: =3 -> 3 | V5: =3 -> 3 | W5: =3 -> 3
D6: 203 | E6: Camion | F6: =VLOOKUP(D6,Vehicule!E:Q,5,0) -> 245 | G6: 5 | H6: 8 | I6: 9 | J6: 14 | K6: 11 | L6: 21 | M6: =SUM(Table6[[#This Row],[IANUARIE]:[IUNIE]])*Table6[[#This Row],[TARIF/KM]] -> 16660 | R6: >3 | S6: >6 | T6: >8 | U6: >12 | V6: >13 | W6: >14
D7: 205 | E7: Camion | F7: =VLOOKUP(D7,Vehicule!E:Q,5,0) -> 245 | G7: 2 | H7: 3 | I7: 7 | J7: 11 | K7: 16 | L7: 20 | M7: =SUM(Table6[[#This Row],[IANUARIE]:[IUNIE]])*Table6[[#This Row],[TARIF/KM]] -> 14455
D8: 301 | E8: Camion | F8: =VLOOKUP(D8,Vehicule!E:Q,5,0) -> 245 | G8: 4 | H8: 6 | I8: 8 | J8: 11 | K8: 14 | L8: 19 | M8: =SUM(Table6[[#This Row],[IANUARIE]:[IUNIE]])*Table6[[#This Row],[TARIF/KM]] -> 15190
D9: 303 | E9: Camion | F9: =VLOOKUP(D9,Vehicule!E:Q,5,0) -> 245 | G9: 2 | H9: 5 | I9: 7 | J9: 12 | K9: 14 | L9: 18 | M9: =SUM(Table6[[#This Row],[IANUARIE]:[IUNIE]])*Table6[[#This Row],[TARIF/KM]] -> 14210
D10: 305 | E10: Camion | F10: =VLOOKUP(D10,Vehicule!E:Q,5,0) -> 245 | G10: 4 | H10: 6 | I10: 8 | J10: 11 | K10: 15 | L10: 19 | M10: =SUM(Table6[[#This Row],[IANUARIE]:[IUNIE]])*Table6[[#This Row],[TARIF/KM]] -> 15435
D11: 401 | E11: Camion | F11: =VLOOKUP(D11,Vehicule!E:Q,5,0) -> 280 | G11: 4 | H11: 5 | I11: 7 | J11: 13 | K11: 15 | L11: 17 | M11: =SUM(Table6[[#This Row],[IANUARIE]:[IUNIE]])*Table6[[#This Row],[TARIF/KM]] -> 17080
D12: 403 | E12: Camion | F12: =VLOOKUP(D12,Vehicule!E:Q,5,0) -> 245 | G12: 5 | H12: 7 | I12: 9 | J12: 12 | K12: 16 | L12: 20 | M12: =SUM(Table6[[#This Row],[IANUARIE]:[IUNIE]])*Table6[[#This Row],[TARIF/KM]] -> 16905
D13: 405 | E13: Camion | F13: =VLOOKUP(D13,Vehicule!E:Q,5,0) -> 280 | G13: 3 | H13: 4 | I13: 7 | J13: 12 | K13: 16 | L13: 21 | M13: =SUM(Table6[[#This Row],[IANUARIE]:[IUNIE]])*Table6[[#This Row],[TARIF/KM]] -> 17640
D14: 501 | E14: Camion | F14: =VLOOKUP(D14,Vehicule!E:Q,5,0) -> 245 | G14: 4 | H14: 8 | I14: 8 | J14: 11 | K14: 15 | L14: 21 | M14: =SUM(Table6[[#This Row],[IANUARIE]:[IUNIE]])*Table6[[#This Row],[TARIF/KM]] -> 16415
D15: 503 | E15: Camion | F15: =VLOOKUP(D15,Vehicule!E:Q,5,0) -> 280 | G15: 4 | H15: 7 | I15: 10 | J15: 12 | K15: 14 | L15: 14 | M15: =SUM(Table6[[#This Row],[IANUARIE]:[IUNIE]])*Table6[[#This Row],[TARIF/KM]] -> 17080
D16: 202 | E16: Duba | F16: =VLOOKUP(D16,Vehicule!E:Q,5,0) -> 465 | G16: 5 | H16: 6 | I16: 7 | J16: 14 | K16: 17 | L16: 13 | M16: =SUM(Table6[[#This Row],[IANUARIE]:[IUNIE]])*Table6[[#This Row],[TARIF/KM]] -> 28830
D17: 204 | E17: Duba | F17: =VLOOKUP(D17,Vehicule!E:Q,5,0) -> 465 | G17: 4 | H17: 5 | I17: 8 | J17: 12 | K17: 16 | L17: 21 | M17: =SUM(Table6[[#This Row],[IANUARIE]:[IUNIE]])*Table6[[#This Row],[TARIF/KM]] -> 30690
D18: 206 | E18: Duba | F18: =VLOOKUP(D18,Vehicule!E:Q,5,0) -> 465 | G18: 2 | H18: 6 | I18: 9 | J18: 13 | K18: 15 | L18: 12 | M18: =SUM(Table6[[#This Row],[IANUARIE]:[IUNIE]])*Table6[[#This Row],[TARIF/KM]] -> 26505
... D54: 2 | E54: Platforma | F54: =VLOOKUP(D54,Vehicule!E:Q,5,0) -> 6545 | G54: 0 | H54: 1 | I54: 1 | J54: 4 | K54: 6 | L54: 7 | M54: =SUM(Table6[[#This Row],[IANUARIE]:[IUNIE]])*Table6[[#This Row],[TARIF/KM]] -> 124355

Sheet Raport_S1
D4: TIP VEHICUL | E4: Sum of Preț/Noapte | F4: Sum of Ianuarie | G4: Sum of Februarie | H4: Sum of Martie | I4: Sum of Aprilie | J4: Sum of Mai | K4: Sum of Iunie | L4: Sum of Total
D5: Duba | E5: 5220 | F5: 43 | G5: 64 | H5: 86 | I5: 140 | J5: 178 | K5: 198 | L5: 336545
D6: Autocar | E6: 7580 | F6: 39 | G6: 65 | H6: 92 | I6: 140 | J6: 171 | K6: 190 | L6: 480295
D7: Camion | E7: 2800 | F7: 43 | G7: 66 | H7: 90 | I7: 131 | J7: 161 | K7: 209 | L7: 177975
D8: Semiremorca | E8: 5500 | F8: 14 | G8: 31 | H8: 40 | I8: 65 | J8: 74 | K8: 92 | L8: 347600
D9: Trailer | E9: 8225 | F9: 10 | G9: 27 | H9: 37 | I9: 60 | J9: 63 | K9: 90 | L9: 472115
D10: Autoutilitara | E10: 4525 | F10: 19 | G10: 26 | H10: 37 | I10: 67 | J10: 79 | K10: 101 | L10: 296605
D11: Platforma | E11: 13090 | F11: 1 | G11: 2 | H11: 3 | I11: 7 | J11: 10 | K11: 12 | L11: 229075
D12: Grand Total | E12: 46940 | F12: 169 | G12: 281 | H12: 385 | I12: 610 | J12: 736 | K12: 892 | L12: 2340210
D41: =HLOOKUP(D5,D5:L11,5,0) -> Trailer | E41: =HLOOKUP(E5,E5:M11,5,0) -> 8225 | F41: =HLOOKUP(F5,F5:N11,5,0) -> 10 | G41: =HLOOKUP(G5,G5:O11,5,0) -> 27 | H41: =HLOOKUP(H5,H5:P11,5,0) -> 37 | I41: =HLOOKUP(I5,I5:Q11,5,0) -> 60 | J41: =HLOOKUP(J5,J5:R11,5,0) -> 63 | K41: =HLOOKUP(K5,K5:S11,5,0) -> 90 | L41: =HLOOKUP(L5,L5:T11,5,0) -> 472115
D42: =HLOOKUP(D6,D6:L12,5,0) -> Autoutilitara | E42: =HLOOKUP(E6,E6:M12,5,0) -> 4525 | F42: =HLOOKUP(F6,F6:N12,5,0) -> 19 | G42: =HLOOKUP(G6,G6:O12,5,0) -> 26 | H42: =HLOOKUP(H6,H6:P12,5,0) -> 37 | I42: =HLOOKUP(I6,I6:Q12,5,0) -> 67 | J42: =HLOOKUP(J6,J6:R12,5,0) -> 79 | K42: =HLOOKUP(K6,K6:S12,5,0) -> 101 | L42: =HLOOKUP(L6,L6:T12,5,0) -> 296605
D43: =HLOOKUP(D7,D7:L13,5,0) -> Platforma | E43: =HLOOKUP(E7,E7:M13,5,0) -> 13090 | F43: =HLOOKUP(F7,F7:N13,5,0) -> 1 | G43: =HLOOKUP(G7,G7:O13,5,0) -> 2 | H43: =HLOOKUP(H7,H7:P13,5,0) -> 3 | I43: =HLOOKUP(I7,I7:Q13,5,0) -> 7 | J43: =HLOOKUP(J7,J7:R13,5,0) -> 10 | K43: =HLOOKUP(K7,K7:S13,5,0) -> 12 | L43: =HLOOKUP(L7,L7:T13,5,0) -> 229075
BN90: Row Labels | BO90: Sum of Ianuarie | BP90: Sum of Februarie | BQ90: Sum of Martie | BR90: Sum of Aprilie | BS90: Sum of Mai | BT90: Sum of Iunie
BN91: Duba | BO91: 43 | BP91: 64 | BQ91: 86 | BR91: 140 | BS91: 178 | BT91: 198
BN92: Autocar | BO92: 39 | BP92: 65 | BQ92: 92 | BR92: 140 | BS92: 171 | BT92: 190
BN93: Camion | BO93: 43 | BP93: 66 | BQ93: 90 | BR93: 131 | BS93: 161 | BT93: 209
BN94: Semiremorca | BO94: 14 | BP94: 31 | BQ94: 40 | BR94: 65 | BS94: 74 | BT94: 92
BN95: Trailer | BO95: 10 | BP95: 27 | BQ95: 37 | BR95: 60 | BS95: 63 | BT95: 90
BN96: Autoutilitara | BO96: 19 | BP96: 26 | BQ96: 37 | BR96: 67 | BS96: 79 | BT96: 101
BN97: Platforma | BO97: 1 | BP97: 2 | BQ97: 3 | BR97: 7 | BS97: 10 | BT97: 12
BN98: Grand Total | BO98: 169 | BP98: 281 | BQ98: 385 | BR98: 610 | BS98: 736 | BT98: 892

Sheet Clienti_Fideli
D4: NUME | E4: PRENUME | F4: VÂRSTĂ | G4: DATA NAȘTERII | H4: Urmatoarea zi de nastere | I4: ZILE PÂNĂ LA URM. ZI DE NAȘTERE | J4: SEX | K4: ȚARA | L4: ADRESA | M4: ADRESA DE E-MAIL | N4: NR. TELEFON | O4: TIPUL PREFERAT DE VEHICUL | P4: MEDIA CURSELOR / LUNA | Q4: TOTAL KM PARCURSI | R4: ULTIMA CURSA | V4: Data de azi | W4: =TODAY() -> 43842
D5: Cristea | E5: Radu | F5: =(YEAR(TODAY())- YEAR(G5)) -> 42 | G5: 28644 | H5: 43985 | I5: =H5-$W$4 -> 143 | J5: M | K5: Franța | L5: Storchgasse 9 | M5: raducristea@gmail.com | N5: 9947436 | O5: Autocar | P5: 3 | Q5: 18 | R5: 43651
D6: Popa | E6: Ioana | F6: =(YEAR(TODAY())- YEAR(G6)) -> 38 | G6: 30109 | H6: 43989 | I6: =H6-$W$4 -> 147 | J6: F | K6: Elveția | L6: Kartnerstrasse 55 | M6: ioanapopa@gmail.com | N6: 4847262 | O6: Autoutilitara | P6: 3 | Q6: 22 | R6: 43777
D7: Muntean | E7: Ion | F7: =(YEAR(TODAY())- YEAR(G7)) -> 30 | G7: 33181 | H7: 44139 | I7: =H7-$W$4 -> 297 | J7: M | K7: Romania | L7: Calea Dumbrăvii 6 | M7: ionmuntean@gmail.com | N7: 3838762 | O7: Trailer | P7: 4 | Q7: 41 | R7: 43715
D8: Bolta | E8: George | F8: =(YEAR(TODAY())- YEAR(G8)) -> 27 | G8: 34235 | H8: 44097 | I8: =H8-$W$4 -> 255 | J8: M | K8: Germania | L8: Stefan Cel Mare 8 | M8: georgebolta@yahoo.com | N8: 3746335 | O8: Duba | P8: 5 | Q8: 31 | R8: 43442
D9: Barbu | E9: Andreea | F9: =(YEAR(TODAY())- YEAR(G9)) -> 36 | G9: 30845 | H9: 43994 | I9: =H9-$W$4 -> 152 | J9: F | K9: Monaco | L9: Ullmanstasse 6 | M9: andreeabarbu@yahoo.com | N9: 7365242 | O9: Platforma | P9: 7 | Q9: 20 | R9: 43653
D10: Radu | E10: David | F10: =(YEAR(TODAY())- YEAR(G10)) -> 33 | G10: 31961 | H10: 44015 | I10: =H10-$W$4 -> 173 | J10: M | K10: Suedia | L10: Strada Lungă 8 | M10: davidradu@yahoo.com | N10: 3622828 | O10: Camion | P10: 6 | Q10: 8 | R10: 43472
D11: Roman | E11: Alexandru | F11: =(YEAR(TODAY())- YEAR(G11)) -> 28 | G11: 33728 | H11: 43955 | I11: =H11-$W$4 -> 113 | J11: M | K11: Romania | L11: Nicolae Bălcescu 7 | M11: alexandruroman@gmail.com | N11: 8484736 | O11: Semiremorca | P11: 2 | Q11: 16 | R11: 43484
D12: Filip | E12: Mircea | F12: =(YEAR(TODAY())- YEAR(G12)) -> 41 | G12: 29015 | H12: 43991 | I12: =H12-$W$4 -> 149 | J12: M | K12: Monaco | L12: Mihai Eminescu 67 | M12: mirceafilip@gmail.com | N12: 5364484 | O12: Autocar | P12: 3 | Q12: 23 | R12: 43621
D13: Popescu | E13: Oana | F13: =(YEAR(TODAY())- YEAR(G13)) -> 33 | G13: 31914 | H13: 43968 | I13: =H13-$W$4 -> 126 | J13: F | K13: Franța | L13: Flroilor 9 | M13: oanapopescu@gmail.com | N13: 7463357 | O13: Trailer | P13: 6 | Q13: 42 | R13: 43716
D14: Tudor | E14: Paul | F14: =(YEAR(TODAY())- YEAR(G14)) -> 32 | G14: 32316 | H14: 44004 | I14: =H14-$W$4 -> 162 | J14: M | K14: Austria | L14: George Coșbuc 17 | M14: paultudor@yahoo.com | N14: 8383736 | O14: Semiremorca | P14: 7 | Q14: 26 | R14: 43536
D15: Teodorescu | E15: Daria | F15: =(YEAR(TODAY())- YEAR(G15)) -> 43 | G15: 28170 | H15: 43875 | I15: =H15-$W$4 -> 33 | J15: F | K15: Germania | L15: Teilor 7 | M15: dariateodorescu@yahoo.com | N15: 8483737 | O15: Camion | P15: 9 | Q15: 14 | R15: 43715
D16: Badea | E16: Robert | F16: =(YEAR(TODAY())- YEAR(G16)) -> 26 | G16: 34490 | H16: 43987 | I16: =H16-$W$4 -> 145 | J16: M | K16: Danemarca | L16: Unirii 25 | M16: robertbadea@gmail.com | N16: 8484733 | O16: Autocar | P16: 5 | Q16: 15 | R16: 43585
... D19: Pop | E19: Tudor | F19: =(YEAR(TODAY())- YEAR(G19)) -> 29 | G19: 33426 | H19: 44019 | I19: =H19-$W$4 -> 177 | J19: M | K19: Suedia | L19: Libertății 7 | M19: tudorpop@yahoo.com | N19: 7636352 | O19: Camion | P19: 4 | Q19: 9 | R19: 43692

Sheet Clienti_Curenti
D4: NUME | E4: PRENUME | F4: NR VEHICUL | G4: TIP VEHICUL | H4: DATA PLECARE | I4: DATA SOSIRE | J4: NR.TELEFON | K4: E-MAIL | L4: TIP MARFA | M4: NR VEHICUL | N4: TRANSPORT AEROPORT
D5: Tudor | E5: Adela | F5: 203 | G5: =VLOOKUP(F5,Curse_S1!D:M,2,0) -> Camion | H5: =VLOOKUP(F5,Vehicule!E:N,9,0) -> 43670 | I5: =VLOOKUP(F5,Vehicule!E:N,10,0) -> 43673 | J5: 333488388 | K5: =_xlfn.CONCAT(D5,".",E5,"@gmail.com") -> Tudor.Adela@gmail.com | L5: Da | M5: NJ8776T
D6: Costea | E6: Valentin | F6: 205 | G6: =VLOOKUP(F6,Curse_S1!D:M,2,0) -> Camion | H6: =VLOOKUP(F6,Vehicule!E:N,9,0) -> 43665 | I6: =VLOOKUP(F6,Vehicule!E:N,10,0) -> 43675 | J6: 748366338 | K6: =_xlfn.CONCAT(D6,".",E6,"@gmail.com") -> Costea.Valentin@gmail.com | L6: Da | M6: B5666TT
D7: Bârsănescu | E7: Rebecca | F7: 301 | G7: =VLOOKUP(F7,Curse_S1!D:M,2,0) -> Camion | H7: =VLOOKUP(F7,Vehicule!E:N,9,0) -> 43668 | I7: =VLOOKUP(F7,Vehicule!E:N,10,0) -> 47325 | J7: 363638883 | K7: =_xlfn.CONCAT(D7,".",E7,"@gmail.com") -> Bârsănescu.Rebecca@gmail.com | L7: Da | M7: OT677P00
D8: Cămătaru | E8: Dragomir | F8: 305 | G8: =VLOOKUP(F8,Curse_S1!D:M,2,0) -> Camion | H8: =VLOOKUP(F8,Vehicule!E:N,9,0) -> 43669 | I8: =VLOOKUP(F8,Vehicule!E:N,10,0) -> 43674 | J8: 746374883 | K8: =_xlfn.CONCAT(D8,".",E8,"@gmail.com") -> Cămătaru.Dragomir @gmail.com | L8: Nu | N8: Da
D9: Morar | E9: Isabela | F9: 401 | G9: =VLOOKUP(F9,Curse_S1!D:M,2,0) -> Camion | H9: =VLOOKUP(F9,Vehicule!E:N,9,0) -> 43671 | I9: =VLOOKUP(F9,Vehicule!E:N,10,0) -> 43672 | J9: 737488628 | K9: =_xlfn.CONCAT(D9,".",E9,"@gmail.com") -> Morar.Isabela@gmail.com | L9: Da | M9: G665
D10: Pârvulescu | E10: Eduard | F10: 403 | G10: =VLOOKUP(F10,Curse_S1!D:M,2,0) -> Camion | H10: =VLOOKUP(F10,Vehicule!E:N,9,0) -> 43670 | I10: =VLOOKUP(F10,Vehicule!E:N,10,0) -> 43675 | J10: 737748287 | K10: =_xlfn.CONCAT(D10,".",E10,"@gmail.com") -> Pârvulescu.Eduard @gmail.com | L10: Nu | N10: Da
D11: Manea | E11: Ionut | F11: 501 | G11: =VLOOKUP(F11,Curse_S1!D:M,2,0) -> Camion | H11: =VLOOKUP(F11,Vehicule!E:N,9,0) -> 43669 | I11: =VLOOKUP(F11,Vehicule!E:N,10,0) -> 43671 | J11: 77953736 | K11: =_xlfn.CONCAT(D11,".",E11,"@gmail.com") -> Manea.Ionut@gmail.com | L11: Nu | N11: Da
D12: Voica | E12: Alin | F12: 503 | G12: =VLOOKUP(F12,Curse_S1!D:M,2,0) -> Camion | H12: =VLOOKUP(F12,Vehicule!E:N,9,0) -> 43666 | I12: =VLOOKUP(F12,Vehicule!E:N,10,0) -> 43671 | J12: 626738958 | K12: =_xlfn.CONCAT(D12,".",E12,"@gmail.com") -> Voica.Alin@gmail.com | L12: Nu | N12: Da
D13: Cârțan | E13: Iulian | F13: 202 | G13: =VLOOKUP(F13,Curse_S1!D:M,2,0) -> Duba | H13: =VLOOKUP(F13,Vehicule!E:N,9,0) -> 43668 | I13: =VLOOKUP(F13,Vehicule!E:N,10,0) -> 43673 | J13: 77593034 | K13: =_xlfn.CONCAT(D13,".",E13,"@gmail.com") -> Cârțan.Iulian@gmail.com | L13: Da | M13: 6635TT35
D14: Botnaru | E14: Dragos | F14: 204 | G14: =VLOOKUP(F14,Curse_S1!D:M,2,0) -> Duba | H14: =VLOOKUP(F14,Vehicule!E:N,9,0) -> 43669 | I14: =VLOOKUP(F14,Vehicule!E:N,10,0) -> 43673 | J14: 44231566 | K14: =_xlfn.CONCAT(D14,".",E14,"@gmail.com") -> Botnaru.Dragos @gmail.com | L14: Da | M14: H6365
D15: Pîrvu | E15: Roxana | F15: 302 | G15: =VLOOKUP(F15,Curse_S1!D:M,2,0) -> Duba | H15: =VLOOKUP(F15,Vehicule!E:N,9,0) -> 43668 | I15: =VLOOKUP(F15,Vehicule!E:N,10,0) -> 43671 | J15: 7784366453 | K15: =_xlfn.CONCAT(D15,".",E15,"@gmail.com") -> Pîrvu.Roxana@gmail.com | L15: Da | M15: U73645
D16: Chelaru | E16: Mariana | F16: 304 | G16: =VLOOKUP(F16,Curse_S1!D:M,2,0) -> Duba | H16: =VLOOKUP(F16,Vehicule!E:N,9,0) -> 43667 | I16: =VLOOKUP(F16,Vehicule!E:N,10,0) -> 43672 | J16: 728346635 | K16: =_xlfn.CONCAT(D16,".",E16,"@gmail.com") -> Chelaru.Mariana @gmail.com | L16: Da | M16: O99I9
D17: Bruno | E17: Klaus | F17: 402 | G17: =VLOOKUP(F17,Curse_S1!D:M,2,0) -> Duba | H17: =VLOOKUP(F17,Vehicule!E:N,9,0) -> 43668 | I17: =VLOOKUP(F17,Vehicule!E:N,10,0) -> 43675 | J17: 66253478 | K17: =_xlfn.CONCAT(D17,".",E17,"@gmail.com") -> Bruno .Klaus@gmail.com | L17: Nu | N17: Da
D18: Călugăreanu | E18: Nicolina | F18: 404 | G18: =VLOOKUP(F18,Curse_S1!D:M,2,0) -> Duba | H18: =VLOOKUP(F18,Vehicule!E:N,9,0) -> 43671 | I18: =VLOOKUP(F18,Vehicule!E:N,10,0) -> 43672 | J18: 773836467 | K18: =_xlfn.CONCAT(D18,".",E18,"@gmail.com") -> Călugăreanu.Nicolina@gmail.com | L18: Nu | N18: Da
D19: Ivan | E19: Teodor | F19: 406 | G19: =VLOOKUP(F19,Curse_S1!D:M,2,0) -> Duba | H19: =VLOOKUP(F19,Vehicule!E:N,9,0) -> 43670 | I19: =VLOOKUP(F19,Vehicule!E:N,10,0) -> 43672 | J19: 663725533 | K19: =_xlfn.CONCAT(D19,".",E19,"@gmail.com") -> Ivan .Teodor@gmail.com | L19: Da | M19: NMFMDM4
D20: Papacioc | E20: Bennie | F20: 504 | G20: =VLOOKUP(F20,Curse_S1!D:M,2,0) -> Duba | H20: =VLOOKUP(F20,Vehicule!E:N,9,0) -> 43668 | I20: =VLOOKUP(F20,Vehicule!E:N,10,0) -> 43674 | J20: 77384638 | K20: =_xlfn.CONCAT(D20,".",E20,"@gmail.com") -> Papacioc.Bennie @gmail.com | L20: Nu | N20: Da
D21: Hurmuzescu | E21: Andra | F21: 207 | G21: =VLOOKUP(F21,Curse_S1!D:M,2,0) -> Autocar | H21: =VLOOKUP(F21,Vehicule!E:N,9,0) -> 43667 | I21: =VLOOKUP(F21,Vehicule!E:N,10,0) -> 43671 | J21: 52437382 | K21: =_xlfn.CONCAT(D21,".",E21,"@gmail.com") -> Hurmuzescu.Andra @gmail.com | L21: Nu | N21: Da
D22: Pușcaș | E22: Romeo | F22: 208 | G22: =VLOOKUP(F22,Curse_S1!D:M,2,0) -> Autocar | H22: =VLOOKUP(F22,Vehicule!E:N,9,0) -> 43669 | I22: =VLOOKUP(F22,Vehicule!E:N,10,0) -> 43674 | J22: 783625833 | K22: =_xlfn.CONCAT(D22,".",E22,"@gmail.com") -> Pușcaș.Romeo @gmail.com | L22: Nu | N22: Da
D23: Mihăilă | E23: Flaviu | F23: 209 | G23: =VLOOKUP(F23,Curse_S1!D:M,2,0) -> Autocar | H23: =VLOOKUP(F23,Vehicule!E:N,9,0) -> 43670 | I23: =VLOOKUP(F23,Vehicule!E:N,10,0) -> 43672 | J23: 773838292 | K23: =_xlfn.CONCAT(D23,".",E23,"@gmail.com") -> Mihăilă.Flaviu @gmail.com | L23: Nu | N23: Da
D24: Săulescu | E24: Rudolf | F24: 307 | G24: =VLOOKUP(F24,Curse_S1!D:M,2,0) -> Autocar | H24: =VLOOKUP(F24,Vehicule!E:N,9,0) -> 43670 | I24: =VLOOKUP(F24,Vehicule!E:N,10,0) -> 43672 | J24: 737483736 | K24: =_xlfn.CONCAT(D24,".",E24,"@gmail.com") -> Săulescu.Rudolf @gmail.com | L24: Da | M24: JFHET5563
D25: Ciucurescu | E25: Anisia | F25: 308 | G25: =VLOOKUP(F25,Curse_S1!D:M,2,0) -> Autocar | H25: =VLOOKUP(F25,Vehicule!E:N,9,0) -> 43665 | I25: =VLOOKUP(F25,Vehicule!E:N,10,0) -> 43672 | J25: 737625345 | K25: =_xlfn.CONCAT(D25,".",E25,"@gmail.com") -> Ciucurescu.Anisia@gmail.com | L25: Da | M25: JJEH778E
D26: Mihnea | E26: Fernando | F26: 407 | G26: =VLOOKUP(F26,Curse_S1!D:M,2,0) -> Autocar | H26: =VLOOKUP(F26,Vehicule!E:N,9,0) -> 43666 | I26: =VLOOKUP(F26,Vehicule!E:N,10,0) -> 43675 | J26: 373828293 | K26: =_xlfn.CONCAT(D26,".",E26,"@gmail.com") -> Mihnea.Fernando @gmail.com | L26: Nu | N26: Da
D27: Voicu | E27: Roland | F27: 408 | G27: =VLOOKUP(F27,Curse_S1!D:M,2,0) -> Autocar | H27: =VLOOKUP(F27,Vehicule!E:N,9,0) -> 43668 | I27: =VLOOKUP(F27,Vehicule!E:N,10,0) -> 43671 | J27: 738264737 | K27: =_xlfn.CONCAT(D27,".",E27,"@gmail.com") -> Voicu.Roland @gmail.com | L27: Nu | N27: Da
D28: Necula | E28: Konstantin | F28: 409 | G28: =VLOOKUP(F28,Curse_S1!D:M,2,0) -> Autocar | H28: =VLOOKUP(F28,Vehicule!E:N,9,0) -> 43670 | I28: =VLOOKUP(F28,Vehicule!E:N,10,0) -> 43672 | J28: 72635483 | K28: =_xlfn.CONCAT(D28,".",E28,"@gmail.com") -> Necula.Konstantin @gmail.com | L28: Da | M28: 3EDDSDE2
D29: Morar | E29: Viorel | F29: 507 | G29: =VLOOKUP(F29,Curse_S1!D:M,2,0) -> Autocar | H29: =VLOOKUP(F29,Vehicule!E:N,9,0) -> 43669 | I29: =VLOOKUP(F29,Vehicule!E:N,10,0) -> 43673 | J29: 63728463 | K29: =_xlfn.CONCAT(D29,".",E29,"@gmail.com") -> Morar.Viorel @gmail.com | L29: Da | M29: HGTTE53
D30: Ivan | E30: Magdalena | F30: 508 | G30: =VLOOKUP(F30,Curse_S1!D:M,2,0) -> Autocar | H30: =VLOOKUP(F30,Vehicule!E:N,9,0) -> 43669 | I30: =VLOOKUP(F30,Vehicule!E:N,10,0) -> 43671 | J30: 738438837 | K30: =_xlfn.CONCAT(D30,".",E30,"@gmail.com") -> Ivan .Magdalena@gmail.com | L30: Da | M30: JFKDG655
D31: Croitor | E31: Dumitru | F31: 310 | G31: =VLOOKUP(F31,Curse_S1!D:M,2,0) -> Autoutilitara | H31: =VLOOKUP(F31,Vehicule!E:N,9,0) -> 43667 | I31: =VLOOKUP(F31,Vehicule!E:N,10,0) -> 43674 | J31: 6372635343 | K31: =_xlfn.CONCAT(D31,".",E31,"@gmail.com") -> Croitor.Dumitru @gmail.com | L31: Da | M31: KDJFBC666
D32: Manea | E32: Sandu | F32: 410 | G32: =VLOOKUP(F32,Curse_S1!D:M,2,0) -> Autoutilitara | H32: =VLOOKUP(F32,Vehicule!E:N,9,0) -> 43671 | I32: =VLOOKUP(F32,Vehicule!E:N,10,0) -> 43675 | J32: 8392929237 | K32: =_xlfn.CONCAT(D32,".",E32,"@gmail.com") -> Manea.Sandu @gmail.com | L32: Nu | N32: Da
D33: Dăscălescu | E33: Rodica | F33: 510 | G33: =VLOOKUP(F33,Curse_S1!D:M,2,0) -> Autoutilitara | H33: =VLOOKUP(F33,Vehicule!E:N,9,0) -> 43670 | I33: =VLOOKUP(F33,Vehicule!E:N,10,0) -> 43671 | J33: 6466363527 | K33: =_xlfn.CONCAT(D33,".",E33,"@gmail.com") -> Dăscălescu.Rodica@gmail.com | L33: Nu | N33: Da
D34: Oprea | E34: Albert | F34: 411 | G34: =VLOOKUP(F34,Curse_S1!D:M,2,0) -> Semiremorca | H34: =VLOOKUP(F34,Vehicule!E:N,9,0) -> 43668 | I34: =VLOOKUP(F34,Vehicule!E:N,10,0) -> 43673 | J34: 737847383 | K34: =_xlfn.CONCAT(D34,".",E34,"@gmail.com") -> Oprea.Albert@gmail.com | L34: Nu | N34: Da
D35: Opriș | E35: Sebastian | F35: 412 | G35: =VLOOKUP(F35,Curse_S1!D:M,2,0) -> Semiremorca | H35: =VLOOKUP(F35,Vehicule!E:N,9,0) -> 43668 | I35: =VLOOKUP(F35,Vehicule!E:N,10,0) -> 43671 | J35: 7363838393 | K35: =_xlfn.CONCAT(D35,".",E35,"@gmail.com") -> Opriș.Sebastian@gmail.com | L35: Nu | N35: Da
D36: Ghiță | E36: Vladimir | F36: 513 | G36: =VLOOKUP(F36,Curse_S1!D:M,2,0) -> Semiremorca | H36: =VLOOKUP(F36,Vehicule!E:N,9,0) -> 43669 | I36: =VLOOKUP(F36,Vehicule!E:N,10,0) -> 43672 | J36: 837473839 | K36: =_xlfn.CONCAT(D36,".",E36,"@gmail.com") -> Ghiță.Vladimir @gmail.com | L36: Da | M36: GLEA00
D37: Olaru | E37: Anton | F37: 104 | G37: =VLOOKUP(F37,Curse_S1!D:M,2,0) -> Semiremorca | H37: =VLOOKUP(F37,Vehicule!E:N,9,0) -> 43670 | I37: =VLOOKUP(F37,Vehicule!E:N,10,0) -> 43673 | J37: 373839394 | K37: =_xlfn.CONCAT(D37,".",E37,"@gmail.com") -> Olaru.Anton@gmail.com | L37: Da | M37: OPHEH4
D38: Ungureanu | E38: Vincenza | F38: 101 | G38: =VLOOKUP(F38,Curse_S1!D:M,2,0) -> Trailer | H38: =VLOOKUP(F38,Vehicule!E:N,9,0) -> 43667 | I38: =VLOOKUP(F38,Vehicule!E:N,10,0) -> 43674 | J38: 636483902 | K38: =_xlfn.CONCAT(D38,".",E38,"@gmail.com") -> Ungureanu.Vincenza@gmail.com | L38: Nu | N38: Da
D39: Bran | E39: Florin | F39: 102 | G39: =VLOOKUP(F39,Curse_S1!D:M,2,0) -> Trailer | H39: =VLOOKUP(F39,Vehicule!E:N,9,0) -> 43668 | I39: =VLOOKUP(F39,Vehicule!E:N,10,0) -> 43672 | J39: 64638383839 | K39: =_xlfn.CONCAT(D39,".",E39,"@gmail.com") -> Bran .Florin @gmail.com | L39: Nu | N39: Da
D40: Neacșu | E40: Margareta | F40: 602 | G40: =VLOOKUP(F40,Curse_S1!D:M,2,0) -> Trailer | H40: =VLOOKUP(F40,Vehicule!E:N,9,0) -> 43671 | I40: =VLOOKUP(F40,Vehicule!E:N,10,0) -> 43674 | J40: 74393948387 | K40: =_xlfn.CONCAT(D40,".",E40,"@gmail.com") -> Neacșu.Margareta@gmail.com | L40: Nu | N40: Da
D41: Dobrogeanu | E41: Samuel | F41: 603 | G41: =VLOOKUP(F41,Curse_S1!D:M,2,0) -> Trailer | H41: =VLOOKUP(F41,Vehicule!E:N,9,0) -> 43669 | I41: =VLOOKUP(F41,Vehicule!E:N,10,0) -> 43675 | J41: 7364497383 | K41: =_xlfn.CONCAT(D41,".",E41,"@gmail.com") -> Dobrogeanu.Samuel @gmail.com | L41: Da | M41: 889HHE
D42: Necula | E42: Sorin | F42: 1 | G42: =VLOOKUP(F42,Curse_S1!D:M,2,0) -> Platforma | H42: =VLOOKUP(F42,Vehicule!E:N,9,0) -> 43667 | I42: =VLOOKUP(F42,Vehicule!E:N,10,0) -> 43673 | J42: 7354839302 | K42: =_xlfn.CONCAT(D42,".",E42,"@gmail.com") -> Necula.Sorin @gmail.com | L42: Da | M42: 2DOOR

Sheet Angajati
D4: Nr. Crt | E4: NUME | F4: PRENUME | G4: CNP | H4: DATA NAȘTERII | I4: SEX | J4: VÂRSTĂ | K4: DATA ANGAJĂRII | L4: VECHIME | M4: VÂRSTA > 30 ANI | N4: FUNCȚIE | O4: SALAR | P4: SCHIMB
D5: 26 | E5: Popa | F5: Radu | G5: 1960817347850 | H5: =DATE(MID(G5,2,2),MID(G5,4,2),MID(G5,6,2)) -> 35294 | I5: =IF(MID(G5,1,1)="1","M","F") -> M | J5: =(YEAR(TODAY())-YEAR(H5)) -> 24 | K5: 42067 | L5: =(YEAR(TODAY())-YEAR(K5)) -> 5 | M5: =IF(J5>30,"DA","NU") -> NU | N5: Șofer | O5: 4500 | P5: 2
D6: 7 | E6: Schuster | F6: Sandra | G6: 2950601214765 | H6: =DATE(MID(G6,2,2),MID(G6,4,2),MID(G6,6,2)) -> 34851 | I6: =IF(MID(G6,1,1)="1","M","F") -> F | J6: =(YEAR(TODAY())-YEAR(H6)) -> 25 | K6: 42858 | L6: =(YEAR(TODAY())-YEAR(K6)) -> 3 | M6: =IF(J6>30,"DA","NU") -> NU | N6: Receptioner | O6: 1000 | P6: 2
D7: 35 | E7: Tomescu | F7: David | G7: 1950402324817 | H7: =DATE(MID(G7,2,2),MID(G7,4,2),MID(G7,6,2)) -> 34791 | I7: =IF(MID(G7,1,1)="1","M","F") -> M | J7: =(YEAR(TODAY())-YEAR(H7)) -> 25 | K7: 42494 | L7: =(YEAR(TODAY())-YEAR(K7)) -> 4 | M7: =IF(J7>30,"DA","NU") -> NU | N7: Șofer | O7: 3500 | P7: 1
D8: 13 | E8: Bica | F8: Ioana | G8: 2941202556645 | H8: =DATE(MID(G8,2,2),MID(G8,4,2),MID(G8,6,2)) -> 34670 | I8: =IF(MID(G8,1,1)="1","M","F") -> F | J8: =(YEAR(TODAY())-YEAR(H8)) -> 26 | K8: 41129 | L8: =(YEAR(TODAY())-YEAR(K8)) -> 8 | M8: =IF(J8>30,"DA","NU") -> NU | N8: Menaj | O8: 1500 | P8: 1
D9: 34 | E9: Vladescu | F9: Andrei | G9: 1940718542109 | H9: =DATE(MID(G9,2,2),MID(G9,4,2),MID(G9,6,2)) -> 34533 | I9: =IF(MID(G9,1,1)="1","M","F") -> M | J9: =(YEAR(TODAY())-YEAR(H9)) -> 26 | K9: 42798 | L9: =(YEAR(TODAY())-YEAR(K9)) -> 3 | M9: =IF(J9>30,"DA","NU") -> NU | N9: Șofer | O9: 3500 | P9: 2
D10: 11 | E10: Mânzat | F10: Paula | G10: 2930114152084 | H10: =DATE(MID(G10,2,2),MID(G10,4,2),MID(G10,6,2)) -> 33983 | I10: =IF(MID(G10,1,1)="1","M","F") -> F | J10: =(YEAR(TODAY())-YEAR(H10)) -> 27 | K10: 41797 | L10: =(YEAR(TODAY())-YEAR(K10)) -> 6 | M10: =IF(J10>30,"DA","NU") -> NU | N10: Receptioner | O10: 2000 | P10: 2
D11: 16 | E11: Pop | F11: Ion | G11: 1930426272907 | H11: =DATE(MID(G11,2,2),MID(G11,4,2),MID(G11,6,2)) -> 34085 | I11: =IF(MID(G11,1,1)="1","M","F") -> M | J11: =(YEAR(TODAY())-YEAR(H11)) -> 27 | K11: 40870 | L11: =(YEAR(TODAY())-YEAR(K11)) -> 9 | M11: =IF(J11>30,"DA","NU") -> NU | N11: Valet | O11: 3000 | P11: 1
D12: 17 | E12: Bâlc | F12: Claudiu | G12: 1930726241832 | H12: =DATE(MID(G12,2,2),MID(G12,4,2),MID(G12,6,2)) -> 34176 | I12: =IF(MID(G12,1,1)="1","M","F") -> M | J12: =(YEAR(TODAY())-YEAR(H12)) -> 27 | K12: 42494 | L12: =(YEAR(TODAY())-YEAR(K12)) -> 4 | M12: =IF(J12>30,"DA","NU") -> NU | N12: Valet | O12: 2000 | P12: 2
D13: 36 | E13: Mânzat | F13: Teodor | G13: 1930809456778 | H13: =DATE(MID(G13,2,2),MID(G13,4,2),MID(G13,6,2)) -> 34190 | I13: =IF(MID(G13,1,1)="1","M","F") -> M | J13: =(YEAR(TODAY())-YEAR(H13)) -> 27 | K13: 40461 | L13: =(YEAR(TODAY())-YEAR(K13)) -> 10 | M13: =IF(J13>30,"DA","NU") -> NU | N13: Șofer | O13: 4500 | P13: 2
D14: 21 | E14: Ionescu | F14: Monica | G14: 2920420462252 | H14: =DATE(MID(G14,2,2),MID(G14,4,2),MID(G14,6,2)) -> 33714 | I14: =IF(MID(G14,1,1)="1","M","F") -> F | J14: =(YEAR(TODAY())-YEAR(H14)) -> 28 | K14: 41246 | L14: =(YEAR(TODAY())-YEAR(K14)) -> 8 | M14: =IF(J14>30,"DA","NU") -> NU | N14: Ajutor Bucătar | O14: 3500 | P14: 1
D15: 1 | E15: Popa | F15: Teodora | G15: 2910915679823 | H15: =DATE(MID(G15,2,2),MID(G15,4,2),MID(G15,6,2)) -> 33496 | I15: =IF(MID(G15,1,1)="1","M","F") -> F | J15: =(YEAR(TODAY())-YEAR(H15)) -> 29 | K15: 42767 | L15: =(YEAR(TODAY())-YEAR(K15)) -> 3 | M15: =IF(J15>30,"DA","NU") -> NU | N15: Receptioner | O15: 1000 | P15: 1
D16: 10 | E16: Dușa | F16: Darius | G16: 1911202393786 | H16: =DATE(MID(G16,2,2),MID(G16,4,2),MID(G16,6,2)) -> 33574 | I16: =IF(MID(G16,1,1)="1","M","F") -> M | J16: =(YEAR(TODAY())-YEAR(H16)) -> 29 | K16: 42951 | L16: =(YEAR(TODAY())-YEAR(K16)) -> 3 | M16: =IF(J16>30,"DA","NU") -> NU | N16: Portar | O16: 1000 | P16: 1
... D37: 33 | E37: Tănase | F37: Razvan | G37: 1830521237805 | H37: =DATE(MID(G37,2,2),MID(G37,4,2),MID(G37,6,2)) -> 30457 | I37: =IF(MID(G37,1,1)="1","M","F") -> M | J37: =(YEAR(TODAY())-YEAR(H37)) -> 37 | K37: 43340 | L37: =(YEAR(TODAY())-YEAR(K37)) -> 2 | M37: =IF(J37>30,"DA","NU") -> DA | N37: Șofer | O37: 2000 | P37: 1
D38: 2 | E38: Moldovan | F38: Teodor | G38: 1811009124376 | H38: =DATE(MID(G38,2,2),MID(G38,4,2),MID(G38,6,2)) -> 29868 | I38: =IF(MID(G38,1,1)="1","M","F") -> M | J38: =(YEAR(TODAY())-YEAR(H38)) -> 39 | K38: 38142 | L38: =(YEAR(TODAY())-YEAR(K38)) -> 16 | M38: =IF(J38>30,"DA","NU") -> DA | N38: Manager | O38: 8000
D39: 38 | E39: Constantinescu | F39: Radu | G39: 1770404567890 | H39: =DATE(MID(G39,2,2),MID(G39,4,2),MID(G39,6,2)) -> 28219 | I39: =IF(MID(G39,1,1)="1","M","F") -> M | J39: =(YEAR(TODAY())-YEAR(H39)) -> 43 | K39: 43286 | L39: =(YEAR(TODAY())-YEAR(K39)) -> 2 | M39: =IF(J39>30,"DA","NU") -> DA | N39: Șofer | O39: 3500 | P39: 3
D40: 29 | E40: Rotar | F40: Robert | G40: 1741226097865 | H40: =DATE(MID(G40,2,2),MID(G40,4,2),MID(G40,6,2)) -> 27389 | I40: =IF(MID(G40,1,1)="1","M","F") -> M | J40: =(YEAR(TODAY())-YEAR(H40)) -> 46 | K40: 41247 | L40: =(YEAR(TODAY())-YEAR(K40)) -> 8 | M40: =IF(J40>30,"DA","NU") -> DA | N40: Șofer | O40: 4500 | P40: 1
D41: 9 | E41: Cristescu | F41: Radu | G41: 1731012436119 | H41: =DATE(MID(G41,2,2),MID(G41,4,2),MID(G41,6,2)) -> 26949 | I41: =IF(MID(G41,1,1)="1","M","F") -> M | J41: =(YEAR(TODAY())-YEAR(H41)) -> 47 | K41: 40605 | L41: =(YEAR(TODAY())-YEAR(K41)) -> 9 | M41: =IF(J41>30,"DA","NU") -> DA | N41: Bucătar Șef | O41: 7500 | P41: 1
D42: 3 | E42: Muntean | F42: Daniela | G42: 2691104987123 | H42: =DATE(MID(G42,2,2),MID(G42,4,2),MID(G42,6,2)) -> 25511 | I42: =IF(MID(G42,1,1)="1","M","F") -> F | J42: =(YEAR(TODAY())-YEAR(H42)) -> 51 | K42: 40079 | L42: =(YEAR(TODAY())-YEAR(K42)) -> 11 | M42: =IF(J42>30,"DA","NU") -> DA | N42: Menaj | O42: 1000 | P42: 1
F45: Total salarii/lună | H45: =SUM(O5:O42) -> 118800
F47: Angajați femei | G47: Angajați bărbați | I47: Vârstă sub 30 | J47: Vârstă peste 30
F48: =COUNTIF(I5:I42,I42) -> 13 | G48: =COUNTIF(I5:I42,I41) -> 25 | I48: =COUNTIF(M5:M42,M20) -> 18 | J48: =COUNTIF(M5:M42,M41) -> 20
