Workbook
Name angajati: Structura!$A$5:$N$22
Name clienti_ing_import: 'Import clienti txt'!$A$3:$O$29
Name fundal_sheet_orepopulate: 'Ore clienti'!$A$1:$U$37
Name Management_Team: Structura!$B$1:$Z$134
Name SalariuNet: 'Bilant Salarii'!$I$4:$I$20
Name ValoareFinala: Credite!$I$4:$I$26

Sheet Acasa
B1: Bine ai venit !
A2: Cine suntem? | B2: Unde ne gasesti? | C2: Structura | D2: Contacteaza-ne! | F2: ING The word is bussines
A4: Curs Valutar ING Romania
A5: Credite
A6: Analiza ore clienti
A7: Planul cladirii
G12: Internet Banking
G13: Economii
G14: Asigurare locuinta
G15: Carduri
G16: ING Jobs
G17: Starea serviciilor
G18: Relatii cu media
A21: =NOW() -> 46044.903 | P21: ING Bank
P22: Duca Robert

Sheet ING
G1: Despre noi
B3: Despre ING | T3: Home
B5: Grupul ING este un grup bancar din Olanda prezent la nivel mondial. Grupul ING a fost creat in anul 1991 prin fuzionare dintre Nationale-Nederlander si NMB Postbank Group. Noul
B6: nume al companiei dupa fuziune a devenit Internatinale Nationale Nederlanden fiind prescurat in I-N-G, dupa care s-a decis schimbarea numelui in ING Groep N.V.
B8: ING Romania
B10: ING Bank România este parte a ING Group. Grupul ING este prezent pe piata din Romania cu afaceri bancare, de asigurari, pensii private, leasing si factoring. ING Bank este prima
B11: instituție financiară internațională care a deschis o sucursală în România după 1989, în prezent deținând o poziție solidă pe piața locală. S-a lansat in 1994, ca bancă de nișă, de
B12: Corporate și Investment Banking, dar s-a dezvoltat într-un ritm susținut, prin creștere organică, iar astăzi este o bancă universală care oferă o paleta completă de produse și servicii
B13: tuturor categoriilor de clienți. ING Bank România funcționează ca o banca universala, servind toate categoriile e clineti prin cele trei divizii specializate: Wholesale Banking, Mid
B14: Corporate și Retail Banking.
B27: Unde ne gasesti?
O28: ING ROMANIA
B29: Sediu central ING Romania | F29: Sucursala ING Sibiu
B30: ING Bank Romania - Expo Business Park, strada Aviator Popisteanu, nr. 54A, cladirea nr. 3, sector 1, Bucuresti, cod postal 012095 | F30: Soseaua Alba Iulia 40, Sibiu, cod postal 550018
B49: Pentru a afla orice sucursala din Romania va rugam, apasati aici.

Sheet Structura
H1: Structura
A3: Tabel detaliat cu angajatii | N3: Home
A5: Cod | B5: Nume | C5: Prenume | D5: CNP | E5: Gen | F5: Data nasterii | G5: Varsta | H5: Varsta sub 35 de ani | I5: Oras natal | J5: Oral actual | K5: Post | L5: Norma (h) | M5: Data angajarii | N5: Vechime
A6: 1 | B6: Bitu | C6: Mihaela | D6: 2701027401457 | E6: =IF(LEFT(Table4[[#This Row],[CNP]],1)="2","F","M") -> F | F6: =DATE(MID(Table4[[#This Row],[CNP]],2,2),MID(Table4[[#This Row],[CNP]],4,2),MID(Table4[[#This Row],[CNP]],6,2)) -> 25868 | G6: =YEAR(TODAY())-YEAR(Table4[[#This Row],[Data nasterii]]) -> 56 | H6: =IF(Table4[[#This Row],[Varsta]]<35,"Se incadreaza","A depasit") -> A depasit | I6: Sibiu | J6: Sibiu | K6: Director executiv | L6: 8 | M6: 38506 | N6: =YEAR(TODAY())-YEAR(Table4[[#This Row],[Data angajarii]]) -> 21
A7: 2 | B7: Boteanu | C7: Bogdan | D7: 1890223457018 | E7: =IF(LEFT(Table4[[#This Row],[CNP]],1)="2","F","M") -> M | F7: =DATE(MID(Table4[[#This Row],[CNP]],2,2),MID(Table4[[#This Row],[CNP]],4,2),MID(Table4[[#This Row],[CNP]],6,2)) -> 32562 | G7: =YEAR(TODAY())-YEAR(Table4[[#This Row],[Data nasterii]]) -> 37 | H7: =IF(Table4[[#This Row],[Varsta]]<35,"Se incadreaza","A depasit") -> A depasit | I7: Timisoara | J7: Sibiu | K7: Deputy CEO & Head of Midcorporate Banking | L7: 8 | M7: 41233 | N7: =YEAR(TODAY())-YEAR(Table4[[#This Row],[Data angajarii]]) -> 14
A8: 3 | B8: Man | C8: Denis | D8: 1880718392078 | E8: =IF(LEFT(Table4[[#This Row],[CNP]],1)="2","F","M") -> M | F8: =DATE(MID(Table4[[#This Row],[CNP]],2,2),MID(Table4[[#This Row],[CNP]],4,2),MID(Table4[[#This Row],[CNP]],6,2)) -> 32342 | G8: =YEAR(TODAY())-YEAR(Table4[[#This Row],[Data nasterii]]) -> 38 | H8: =IF(Table4[[#This Row],[Varsta]]<35,"Se incadreaza","A depasit") -> A depasit | I8: Sibiu | J8: Sibiu | K8: Head of Retail Banking | L8: 8 | M8: 40788 | N8: =YEAR(TODAY())-YEAR(Table4[[#This Row],[Data angajarii]]) -> 15
A9: 4 | B9: Silva | C9: Sergiu | D9: 1741101302427 | E9: =IF(LEFT(Table4[[#This Row],[CNP]],1)="2","F","M") -> M | F9: =DATE(MID(Table4[[#This Row],[CNP]],2,2),MID(Table4[[#This Row],[CNP]],4,2),MID(Table4[[#This Row],[CNP]],6,2)) -> 27334 | G9: =YEAR(TODAY())-YEAR(Table4[[#This Row],[Data nasterii]]) -> 52 | H9: =IF(Table4[[#This Row],[Varsta]]<35,"Se incadreaza","A depasit") -> A depasit | I9: Cluj | J9: Sibiu | K9: Chief Financial Officer | L9: 8 | M9: 40167 | N9: =YEAR(TODAY())-YEAR(Table4[[#This Row],[Data angajarii]]) -> 17
A10: 5 | B10: Octav | C10: Vlad | D10: 1820523108189 | E10: =IF(LEFT(Table4[[#This Row],[CNP]],1)="2","F","M") -> M | F10: =DATE(MID(Table4[[#This Row],[CNP]],2,2),MID(Table4[[#This Row],[CNP]],4,2),MID(Table4[[#This Row],[CNP]],6,2)) -> 30094 | G10: =YEAR(TODAY())-YEAR(Table4[[#This Row],[Data nasterii]]) -> 44 | H10: =IF(Table4[[#This Row],[Varsta]]<35,"Se incadreaza","A depasit") -> A depasit | I10: Valcea | J10: Sibiu | K10: Chief Risk Officer | L10: 8 | M10: 40864 | N10: =YEAR(TODAY())-YEAR(Table4[[#This Row],[Data angajarii]]) -> 15
A11: 6 | B11: Eustin | C11: Silviu | D11: 1721209172890 | E11: =IF(LEFT(Table4[[#This Row],[CNP]],1)="2","F","M") -> M | F11: =DATE(MID(Table4[[#This Row],[CNP]],2,2),MID(Table4[[#This Row],[CNP]],4,2),MID(Table4[[#This Row],[CNP]],6,2)) -> 26642 | G11: =YEAR(TODAY())-YEAR(Table4[[#This Row],[Data nasterii]]) -> 54 | H11: =IF(Table4[[#This Row],[Varsta]]<35,"Se incadreaza","A depasit") -> A depasit | I11: Brasov | J11: Sibiu | K11: Head Of Human Resources | L11: 8 | M11: 39321 | N11: =YEAR(TODAY())-YEAR(Table4[[#This Row],[Data angajarii]]) -> 19
A12: 7 | B12: Matei | C12: Maria-Cristina | D12: 2900314273920 | E12: =IF(LEFT(Table4[[#This Row],[CNP]],1)="2","F","M") -> F | F12: =DATE(MID(Table4[[#This Row],[CNP]],2,2),MID(Table4[[#This Row],[CNP]],4,2),MID(Table4[[#This Row],[CNP]],6,2)) -> 32946 | G12: =YEAR(TODAY())-YEAR(Table4[[#This Row],[Data nasterii]]) -> 36 | H12: =IF(Table4[[#This Row],[Varsta]]<35,"Se incadreaza","A depasit") -> A depasit | I12: Sibiu | J12: Sibiu | K12: Deputy CEO & Chief Operating Officer | L12: 8 | M12: 42286 | N12: =YEAR(TODAY())-YEAR(Table4[[#This Row],[Data angajarii]]) -> 11
A13: 8 | B13: Sighinas | C13: Razvan | D13: 1871010348726 | E13: =IF(LEFT(Table4[[#This Row],[CNP]],1)="2","F","M") -> M | F13: =DATE(MID(Table4[[#This Row],[CNP]],2,2),MID(Table4[[#This Row],[CNP]],4,2),MID(Table4[[#This Row],[CNP]],6,2)) -> 32060 | G13: =YEAR(TODAY())-YEAR(Table4[[#This Row],[Data nasterii]]) -> 39 | H13: =IF(Table4[[#This Row],[Varsta]]<35,"Se incadreaza","A depasit") -> A depasit | I13: Sibiu | J13: Sibiu | K13: Deputy CEO & Chief Information Officer | L13: 8 | M13: 41861 | N13: =YEAR(TODAY())-YEAR(Table4[[#This Row],[Data angajarii]]) -> 12
A14: 9 | B14: Ilie | C14: Florin | D14: 1690210324827 | E14: =IF(LEFT(Table4[[#This Row],[CNP]],1)="2","F","M") -> M | F14: =DATE(MID(Table4[[#This Row],[CNP]],2,2),MID(Table4[[#This Row],[CNP]],4,2),MID(Table4[[#This Row],[CNP]],6,2)) -> 25244 | G14: =YEAR(TODAY())-YEAR(Table4[[#This Row],[Data nasterii]]) -> 57 | H14: =IF(Table4[[#This Row],[Varsta]]<35,"Se incadreaza","A depasit") -> A depasit | I14: Cluj | J14: Sibiu | K14: Deputy CEO & Head of Wholesale Banking | L14: 8 | M14: 39519 | N14: =YEAR(TODAY())-YEAR(Table4[[#This Row],[Data angajarii]]) -> 18
A15: 10 | B15: Popa | C15: Denis | D15: 1910918324891 | E15: =IF(LEFT(Table4[[#This Row],[CNP]],1)="2","F","M") -> M | F15: =DATE(MID(Table4[[#This Row],[CNP]],2,2),MID(Table4[[#This Row],[CNP]],4,2),MID(Table4[[#This Row],[CNP]],6,2)) -> 33499 | G15: =YEAR(TODAY())-YEAR(Table4[[#This Row],[Data nasterii]]) -> 35 | H15: =IF(Table4[[#This Row],[Varsta]]<35,"Se incadreaza","A depasit") -> A depasit | I15: Sibiu | J15: Sibiu | K15: Operating Officer | L15: 8 | M15: 41993 | N15: =YEAR(TODAY())-YEAR(Table4[[#This Row],[Data angajarii]]) -> 12
A16: 11 | B16: Sima | C16: Ioana | D16: 2930517328977 | E16: =IF(LEFT(Table4[[#This Row],[CNP]],1)="2","F","M") -> F | F16: =DATE(MID(Table4[[#This Row],[CNP]],2,2),MID(Table4[[#This Row],[CNP]],4,2),MID(Table4[[#This Row],[CNP]],6,2)) -> 34106 | G16: =YEAR(TODAY())-YEAR(Table4[[#This Row],[Data nasterii]]) -> 33 | H16: =IF(Table4[[#This Row],[Varsta]]<35,"Se incadreaza","A depasit") -> Se incadreaza | I16: Timisoara | J16: Sibiu | K16: Operating Officer | L16: 8 | M16: 42139 | N16: =YEAR(TODAY())-YEAR(Table4[[#This Row],[Data angajarii]]) -> 11
A17: 12 | B17: Mihalache | C17: Daniel | D17: 1871112034827 | E17: =IF(LEFT(Table4[[#This Row],[CNP]],1)="2","F","M") -> M | F17: =DATE(MID(Table4[[#This Row],[CNP]],2,2),MID(Table4[[#This Row],[CNP]],4,2),MID(Table4[[#This Row],[CNP]],6,2)) -> 32093 | G17: =YEAR(TODAY())-YEAR(Table4[[#This Row],[Data nasterii]]) -> 39 | H17: =IF(Table4[[#This Row],[Varsta]]<35,"Se incadreaza","A depasit") -> A depasit | I17: Sibiu | J17: Sibiu | K17: Relationship Manager Corporate | L17: 8 | M17: 41792 | N17: =YEAR(TODAY())-YEAR(Table4[[#This Row],[Data angajarii]]) -> 12
... A22: 17 | B22: Ionescu | C22: Diana | D22: 2920310392842 | E22: =IF(LEFT(Table4[[#This Row],[CNP]],1)="2","F","M") -> F | F22: =DATE(MID(Table4[[#This Row],[CNP]],2,2),MID(Table4[[#This Row],[CNP]],4,2),MID(Table4[[#This Row],[CNP]],6,2)) -> 33673 | G22: =YEAR(TODAY())-YEAR(Table4[[#This Row],[Data nasterii]]) -> 34 | H22: =IF(Table4[[#This Row],[Varsta]]<35,"Se incadreaza","A depasit") -> Se incadreaza | I22: Sibiu | J22: Sibiu | K22: Call Center Officer | L22: 8 | M22: 41095 | N22: =YEAR(TODAY())-YEAR(Table4[[#This Row],[Data angajarii]]) -> 14
D24: ING Bank Management Team
K27: Numarul total de femei angajate: | L27: =COUNTIF(Table4[Gen],"F") -> 5
K28: Numarul total de barbati angajate: | L28: =COUNTIF(Table4[Gen],"M") -> 12
K46: Angajat | L46: Data nasterii | M46: Varsta | N46: Verificare | O46: Verdict
K47: Bitu | L47: =HLOOKUP(L46,angajati,2,0) -> 25868 | M47: =HLOOKUP(M46,A5:G22,2,0) -> 56 | N47: =YEAR(TODAY())-YEAR(L47) -> 56 | O47: =IF(M47=N47,"Corect","Fals") -> Corect
K48: Matei | L48: =HLOOKUP(L46,angajati,8,0) -> 32946 | M48: =HLOOKUP(M46,A5:G22,8,0) -> 36 | N48: =YEAR(TODAY())-YEAR(L48) -> 36 | O48: =IF(M48=N48,"Corect","Fals") -> Corect
K49: Vlad | L49: =HLOOKUP(L46,angajati,15,0) -> 32185 | M49: =HLOOKUP(M46,A5:G22,15,0) -> 38 | N49: =YEAR(TODAY())-YEAR(L49) -> 38 | O49: =IF(M49=N49,"Corect","Fals") -> Corect
K50: Sighinas | L50: =HLOOKUP(L46,angajati,9,0) -> 32060 | M50: =HLOOKUP(M46,A5:G22,9,0) -> 39 | N50: =YEAR(TODAY())-YEAR(L50) -> 39 | O50: =IF(M50=N50,"Corect","Fals") -> Corect
K51: Ioan | L51: =HLOOKUP(L46,angajati,17,0) -> 26549 | M51: =HLOOKUP(M46,A5:G22,17,0) -> 54 | N51: =YEAR(TODAY())-YEAR(L51) -> 54 | O51: =IF(M51=N51,"Corect","Fals") -> Corect
J57: ING The word is bussines

Sheet Ore clienti
G1: Interval orar populat
T2: Home
A3: Analiza a numarului de clienti luand in considerare zilele lucratoare ale saptamanii si intervalul orar. De mentinut ca sucursala este deschisa intre orele 8:00 - 18:00.
C5: ING BANK | D5: Ziua saptamanii Ora | E5: Luni | F5: Marti | G5: Miercuri | H5: Joi | I5: Vineri
D6: 8:00-11:00 | E6: 4 | F6: 2 | G6: 3 | H6: 4 | I6: 3
D7: 11:00-13:00 | E7: 5 | F7: 3 | G7: 4 | H7: 3 | I7: 6
D8: 14:00-16:00 | E8: 6 | F8: 5 | G8: 3 | H8: 5 | I8: 8
D9: 16:00-18:00 | E9: 10 | F9: 8 | G9: 9 | H9: 8 | I9: 12
D10: Total | E10: =SUM(E6:E9) -> 25 | F10: =SUM(F6:F9) -> 18 | G10: =SUM(G6:G9) -> 19 | H10: =SUM(H6:H9) -> 20 | I10: =SUM(I6:I9) -> 29
D11: Target | E11: 20 | F11: 16 | G11: 18 | H11: 23 | I11: 25
B13: Graficul 1.1 reprezinta daca sucursala si-a atins targetul pentru ziua aferenta. | H13: Graficul 1.2 reprezinta o mai buna vizualizare a tabelului si implicit numarul de clienti intr-o saptamana in diferite intervale orare.
D30: (grafic 1.1) | L30: (grafic 1.2)

Sheet Credite
E1: Raport credite | K1: Home
A3: Agent | B3: Tip credit | C3: Valoare (lei) | D3: Data intocmire credit | E3: Data rambursare credit | F3: Status | G3: Numarul de ani pe care a fost facut creditul | H3: Rata dobanzii | I3: Valoarea finala cu dobanda | J3: Procent din valoarea finala | K3: PMT | L3: Valoarea prezenta a sumei de bani cu PMT 0 | M3: Valoarea viitoare a sumei de bani cu PMT 0 | N3: Calculare PMT (marimea platii lunare) | O3: PV cu PMT calculat | P3: FV cu PMT calculat
A4: Bogdan Boteanu | B4: Prima casa | C4: 200000 | D4: 39428 | E4: 50386 | F4: =IF(E4>TODAY(),"In curs de achitare","Achitat") -> In curs de achitare | G4: =DATEDIF(D4,E4,"y") -> 30 | H4: 0.015 | I4: =C4*(1+(G4*H4)) -> 290000 | J4: =I4/I$28 -> 0.1445645 | K4: 0 | L4: =-PV(H4,G4,K4,I4) -> 185531.1 | M4: =-FV(H4,G4,K4,I4) -> 453293.26 | N4: =PMT(H4/12,G4*12,-I4) -> 1000.8486 | O4: =-PV(H4,G4,N4,I4) -> 209567.32 | P4: =-FV(H4,G4,N4,I4) -> 490863.8
A5: Bogdan Boteanu | B5: Credit Imobiliar | C5: 150000 | D5: 38632 | E5: 43838 | F5: =IF(E5>TODAY(),"In curs de achitare","Achitat") -> Achitat | G5: =DATEDIF(D5,E5,"y") -> 14 | H5: 0.028 | I5: =C5*(1+(G5*H5)) -> 208800 | J5: =I5/I$28 -> 0.10408644 | K5: 0 | L5: =-PV(H5,G5,K5,I5) -> 141849.2 | M5: =-FV(H5,G5,K5,I5) -> 307350.62 | N5: =PMT(H5/12,G5*12,-I5) -> 1503.7628 | O5: =-PV(H5,G5,N5,I5) -> 159069.73 | P5: =-FV(H5,G5,N5,I5) -> 332699
A6: Sergiu Silva | B6: Credit de nevoie personale | C6: 15000 | D6: 43203 | E6: 43966 | F6: =IF(E6>TODAY(),"In curs de achitare","Achitat") -> Achitat | G6: =DATEDIF(D6,E6,"y") -> 2 | H6: 0.022 | I6: =C6*(1+(G6*H6)) -> 15660 | J6: =I6/I$28 -> 0.007806483 | K6: 0 | L6: =-PV(H6,G6,K6,I6) -> 14993.049 | M6: =-FV(H6,G6,K6,I6) -> 16356.619 | N6: =PMT(H6/12,G6*12,-I6) -> 667.55811 | O6: =-PV(H6,G6,N6,I6) -> 16285.364 | P6: =-FV(H6,G6,N6,I6) -> 17706.422
A7: Maria-Cristina Matei | B7: Credit auto | C7: 35000 | D7: 41461 | E7: 43711 | F7: =IF(E7>TODAY(),"In curs de achitare","Achitat") -> Achitat | G7: =DATEDIF(D7,E7,"y") -> 6 | H7: 0.065 | I7: =C7*(1+(G7*H7)) -> 48650 | J7: =I7/I$28 -> 0.024251941 | K7: 0 | L7: =-PV(H7,G7,K7,I7) -> 33341.505 | M7: =-FV(H7,G7,K7,I7) -> 70987.273 | N7: =PMT(H7/12,G7*12,-I7) -> 817.80308 | O7: =-PV(H7,G7,N7,I7) -> 37300.501 | P7: =-FV(H7,G7,N7,I7) -> 76764.011
A8: Denis Popa | B8: Credit auto | C8: 50000 | D8: 42370 | E8: 43868 | F8: =IF(E8>TODAY(),"In curs de achitare","Achitat") -> Achitat | G8: =DATEDIF(D8,E8,"y") -> 4 | H8: 0.053 | I8: =C8*(1+(G8*H8)) -> 60600 | J8: =I8/I$28 -> 0.030208995 | K8: 0 | L8: =-PV(H8,G8,K8,I8) -> 49290.036 | M8: =-FV(H8,G8,K8,I8) -> 74505.118 | N8: =PMT(H8/12,G8*12,-I8) -> 1403.8255 | O8: =-PV(H8,G8,N8,I8) -> 54233.438 | P8: =-FV(H8,G8,N8,I8) -> 80582.819
A9: Sergiu Silva | B9: Prima casa | C9: 250000 | D9: 43898 | E9: 51419 | F9: =IF(E9>TODAY(),"In curs de achitare","Achitat") -> In curs de achitare | G9: =DATEDIF(D9,E9,"y") -> 20 | H9: 0.021 | I9: =C9*(1+(G9*H9)) -> 355000 | J9: =I9/I$28 -> 0.17696689 | K9: 0 | L9: =-PV(H9,G9,K9,I9) -> 234268.29 | M9: =-FV(H9,G9,K9,I9) -> 537951.59 | N9: =PMT(H9/12,G9*12,-I9) -> 1812.7468 | O9: =-PV(H9,G9,N9,I9) -> 263625.24 | P9: =-FV(H9,G9,N9,I9) -> 582437.83
A10: Florin Ilie | B10: Credit Imobiliar | C10: 80000 | D10: 36558 | E10: 43628 | F10: =IF(E10>TODAY(),"In curs de achitare","Achitat") -> Achitat | G10: =DATEDIF(D10,E10,"y") -> 19 | H10: 0.029 | I10: =C10*(1+(G10*H10)) -> 124080 | J10: =I10/I$28 -> 0.061853666 | K10: 0 | L10: =-PV(H10,G10,K10,I10) -> 72079.151 | M10: =-FV(H10,G10,K10,I10) -> 213596.39 | N10: =PMT(H10/12,G10*12,-I10) -> 708.48089 | O10: =-PV(H10,G10,N10,I10) -> 82317.709 | P10: =-FV(H10,G10,N10,I10) -> 231221.46
A11: Ioana Sima | B11: Credit de nevoie personale | C11: 10000 | D11: 43819 | E11: 44185 | F11: =IF(E11>TODAY(),"In curs de achitare","Achitat") -> Achitat | G11: =DATEDIF(D11,E11,"y") -> 1 | H11: 0.03 | I11: =C11*(1+(G11*H11)) -> 10300 | J11: =I11/I$28 -> 0.0051345322 | K11: 0 | L11: =-PV(H11,G11,K11,I11) -> 10000 | M11: =-FV(H11,G11,K11,I11) -> 10609 | N11: =PMT(H11/12,G11*12,-I11) -> 872.3451 | O11: =-PV(H11,G11,N11,I11) -> 10846.937 | P11: =-FV(H11,G11,N11,I11) -> 11481.345
A12: Andreea Corpa | B12: Credit auto | C12: 20000 | D12: 42785 | E12: 45736 | F12: =IF(E12>TODAY(),"In curs de achitare","Achitat") -> Achitat | G12: =DATEDIF(D12,E12,"y") -> 8 | H12: 0.03 | I12: =C12*(1+(G12*H12)) -> 24800 | J12: =I12/I$28 -> 0.012362757 | K12: 0 | L12: =-PV(H12,G12,K12,I12) -> 19577.349 | M12: =-FV(H12,G12,K12,I12) -> 31415.898 | N12: =PMT(H12/12,G12*12,-I12) -> 290.89338 | O12: =-PV(H12,G12,N12,I12) -> 21619.331 | P12: =-FV(H12,G12,N12,I12) -> 34002.62
A13: Mihai Vlad | B13: Credit auto | C13: 45000 | D13: 42262 | E13: 44088 | F13: =IF(E13>TODAY(),"In curs de achitare","Achitat") -> Achitat | G13: =DATEDIF(D13,E13,"y") -> 4 | H13: 0.028 | I13: =C13*(1+(G13*H13)) -> 50040 | J13: =I13/I$28 -> 0.024944854 | K13: 0 | L13: =-PV(H13,G13,K13,I13) -> 44806.894 | M13: =-FV(H13,G13,K13,I13) -> 55884.293 | N13: =PMT(H13/12,G13*12,-I13) -> 1103.184 | O13: =-PV(H13,G13,N13,I13) -> 48927.226 | P13: =-FV(H13,G13,N13,I13) -> 60485.848
A14: Florin Ilie | B14: Prima casa | C14: 90000 | D14: 42796 | E14: 51323 | F14: =IF(E14>TODAY(),"In curs de achitare","Achitat") -> In curs de achitare | G14: =DATEDIF(D14,E14,"y") -> 23 | H14: 0.024 | I14: =C14*(1+(G14*H14)) -> 139680 | J14: =I14/I$28 -> 0.069630239 | K14: 0 | L14: =-PV(H14,G14,K14,I14) -> 80953.424 | M14: =-FV(H14,G14,K14,I14) -> 241008.98 | N14: =PMT(H14/12,G14*12,-I14) -> 659.046 | O14: =-PV(H14,G14,N14,I14) -> 92498.717 | P14: =-FV(H14,G14,N14,I14) -> 260929.65
A15: Denis Popa | B15: Credit de nevoie personale | C15: 5000 | D15: 43942 | E15: 44490 | F15: =IF(E15>TODAY(),"In curs de achitare","Achitat") -> Achitat | G15: =DATEDIF(D15,E15,"y") -> 1 | H15: 0.038 | I15: =C15*(1+(G15*H15)) -> 5190 | J15: =I15/I$28 -> 0.002587206 | K15: 0 | L15: =-PV(H15,G15,K15,I15) -> 5000 | M15: =-FV(H15,G15,K15,I15) -> 5387.22 | N15: =PMT(H15/12,G15*12,-I15) -> 441.45389 | O15: =-PV(H15,G15,N15,I15) -> 5425.2928 | P15: =-FV(H15,G15,N15,I15) -> 5828.6739
... A26: Florin Ilie | B26: Credit de nevoie personale | C26: 10000 | D26: 42042 | E26: 42407 | F26: =IF(E26>TODAY(),"In curs de achitare","Achitat") -> Achitat | G26: =DATEDIF(D26,E26,"y") -> 1 | H26: 0.052 | I26: =C26*(1+(G26*H26)) -> 10520 | J26: =I26/I$28 -> 0.0052442018 | K26: 0 | L26: =-PV(H26,G26,K26,I26) -> 10000 | M26: =-FV(H26,G26,K26,I26) -> 11067.04 | N26: =PMT(H26/12,G26*12,-I26) -> 901.55518 | O26: =-PV(H26,G26,N26,I26) -> 10856.992 | P26: =-FV(H26,G26,N26,I26) -> 11968.595
H28: TOTAL VALOARE FINALA | I28: =SUM(ValoareFinala) -> 2006025
B29: Numarul total de credite de tipul " Prima casa " | F29: =COUNTIF(B4:B26,"Prima casa") -> 5
B30: Valoarea totala a creditelor de tipul " Prima casa " | F30: =SUMIF(B4:B26,"Prima casa",C4:C26) -> 740000
B31: Valoarea toata a creditelor de tipul "Prima casa" luand in considereare si dobanda | F31: =SUMIF(B4:B26,"Prima casa",I4:I26) -> 1076120
B32: Cate credite de tip "Prima casa" au fost facute prin intermediu agentului Denis Popa? | F32: =COUNTIFS(B4:B26,"Prima casa",A4:A26,"Denis Popa") -> 1 | H32: Numarul de ani pe care a fost facut creditul - Histograma
B33: Cate credite a facut agentul Denis Popa in total? | F33: =COUNTIF(A4:A26,"Denis Popa") -> 4 | H33: Categorie ani | I33: Bin | J33: Frequency
B34: Care este valoarea totata a creditelor facute de agentul Denis Popa? | F34: =SUMIFS(C4:C26,A4:A26,"Denis Popa") -> 190000 | H34: 5 | I34: 5 | J34: 13
B35: Cate credite au fost achitate pana in prezent? | F35: =COUNTIF(F4:F26,"Achitat") -> 18 | H35: 10 | I35: 10 | J35: 2
B36: Care este valoarea prezenta a celor 290.000 RON daca ar exista PMT 0? | F36: =-PV(H4,G4,K4,I4) -> 185531.1 | H36: 15 | I36: 15 | J36: 1
B37: Care este valoarea viitoare a celor 290.000 RON daca ar exista PMT 0? | F37: =-FV(H4,G4,K4,I4) -> 453293.26 | H37: 20 | I37: 20 | J37: 2
B38: Care ar fii marimea platii lunare facute catre banca pentru creditul de 290.000 RON? | F38: =PMT(H4/12,G4*12,-I4) -> 1000.8486 | H38: 25 | I38: 25 | J38: 3
B39: Care este valoarea prezenta a celor 290.000 RON cu PMT calculat? | F39: =-PV(H4,G4,N4,I4) -> 209567.32 | I39: More | J39: 2
B40: Care este valoarea viitoare a celor 290.000 RON cu PMT calcult? | F40: =-FV(H4,G4,N4,I4) -> 490863.8
B41: Verdict: Exista diferente intre PV calculat cu PMT 0 si PV calculat cu PMT calculat? | F41: =IF(L4=O4,"Nu exista diferente","Exista diferente") -> Exista diferente
B42: Verdict: Exista diferente intre FV calculat cu PMT 0 si PV calculat cu PMT calculat? | F42: =IF(M4=P4,"Nu exista diferente","Exista diferente") -> Exista diferente

Sheet Plan Cladire
J1: Plan cladire
U2: Home
B3: CLIENTI | C3: Dozator apa | E3: Toaleta barbati | H3: Specialist Contract center | L3: Relationship Manager Corporate | P3: Financiar officer
D8: ING Bank
G9: SUPORT | T9: Iesire de urgenta 1
P15: Director executiv
B18: Intrare birouri principale | H18: Call center officer | L18: Operating Office
E19: Toaleta femei
F24: Bancomat 1 | K24: Bancomat 2 | P24: Bancomat 3
T28: Iesire de urgenta 2
E29: ING THE WORD IS BUSINESS
B32: Intrare clienti
I34: Robot achitare facturi 2 | R34: Robot achitare facturi 1
E37: Dozator apa
N38: ING Bank
A43: Planul cladirei este realizat sucursalei din Sibiu, sos. Alba Iulia nr. 40

Sheet Curs Valutar
F1: Curs valutar ING Romania
R2: Home
B3: Imagine | C3: Moneda | D3: Cod | E3: Curs | F3: ING Cumpara | G3: ING Vinde | H3: Curs | I3: Sortare curs
C4: 1 euro | D4: EUR | E4: 4.8425 | F4: 4.7452 | G4: 4.9388 | H4: 4.8425 | I4: 5.5533
C5: 1 dolar american | D5: USD | E5: 4.4955 | F5: 4.3896 | G5: 4.5688 | H5: 4.4955 | I5: 4.8425
C6: 1 lira sterlina | D6: GBP | E6: 5.5533 | F6: 5.4292 | G6: 5.6508 | H6: 5.5533 | I6: 4.4955
C7: 1 franc elvetian | D7: CHF | E7: 4.071 | F7: 4.5132 | G7: 4.6974 | H7: 4.071 | I7: 4.071
C8: 1 dolar australian | D8: AUD | E8: 2.8623 | F8: 2.8035 | G8: 2.9179 | H8: 2.8623 | I8: 2.8623
C9: 1 corona daneza | D9: DKK | E9: 0.6493 | F9: 0.6361 | G9: 0.6621 | H9: 0.6493 | I9: 0.6493
C10: 1 froint unguresc | D10: HUF | E10: 0.0135 | F10: 0.0133 | G10: 0.0138 | H10: 0.0135 | I10: 0.4447
C11: 1 yen japonez | D11: JPY | E11: 0.0418 | F11: 0.0408 | G11: 0.0424 | H11: 0.0418 | I11: 0.4205
C12: 1 corona norvegiana | D12: NOK | E12: 0.4205 | F12: 0.4134 | G12: 0.4302 | H12: 0.4205 | I12: 0.0418
C13: 1 corona suedeza | D13: SEK | E13: 0.4447 | F13: 0.4362 | G13: 0.454 | H13: 0.4447 | I13: 0.0135

Sheet Bilant Salarii
F1: Bilant salarii Aprilie | P1: Home
A3: Cod | B3: Nume | C3: Prenume | D3: Post | E3: Norma | F3: Zile lucrate | G3: Lei pe ora | H3: Bonusuri | I3: Salariu net | J3: Cresteri salariale viitoare
A4: 1 | B4: Bitu | C4: Mihaela | D4: =VLOOKUP(B4,Table4[[Nume]:[Post]],10,0) -> Director executiv | E4: =VLOOKUP(A4,Structura!A6:L22,12,0) -> 8 | F4: 21 | G4: 60 | H4: 1000 | I4: =(G4*E4*F4)+H4 -> 11080 | J4: Bitu
A5: 2 | B5: Boteanu | C5: Bogdan | D5: =VLOOKUP(B5,Table4[[Nume]:[Post]],10,0) -> Deputy CEO & Head of Midcorporate Banking | E5: =VLOOKUP(A5,Structura!A7:L23,12,0) -> 8 | F5: 20 | G5: 42 | H5: 500 | I5: =(G5*E5*F5)+H5 -> 7220 | J5: Man
A6: 3 | B6: Man | C6: Denis | D6: =VLOOKUP(B6,Table4[[Nume]:[Post]],10,0) -> Head of Retail Banking | E6: =VLOOKUP(A6,Structura!A8:L24,12,0) -> 8 | F6: 17 | G6: 43 | H6: 350 | I6: =(G6*E6*F6)+H6 -> 6198 | J6: Eustin
A7: 4 | B7: Silva | C7: Sergiu | D7: =VLOOKUP(B7,Table4[[Nume]:[Post]],10,0) -> Chief Financial Officer | E7: =VLOOKUP(A7,Structura!A9:L25,12,0) -> 8 | F7: 21 | G7: 44 | H7: 200 | I7: =(G7*E7*F7)+H7 -> 7592 | J7: Matei
A8: 5 | B8: Octav | C8: Vlad | D8: =VLOOKUP(B8,Table4[[Nume]:[Post]],10,0) -> Chief Risk Officer | E8: =VLOOKUP(A8,Structura!A10:L26,12,0) -> 8 | F8: 21 | G8: 39 | H8: 300 | I8: =(G8*E8*F8)+H8 -> 6852
A9: 6 | B9: Eustin | C9: Silviu | D9: =VLOOKUP(B9,Table4[[Nume]:[Post]],10,0) -> Head Of Human Resources | E9: =VLOOKUP(A9,Structura!A11:L27,12,0) -> 8 | F9: 20 | G9: 47 | H9: 650 | I9: =(G9*E9*F9)+H9 -> 8170
A10: 7 | B10: Matei | C10: Maria-Cristina | D10: =VLOOKUP(B10,Table4[[Nume]:[Post]],10,0) -> Deputy CEO & Chief Operating Officer | E10: =VLOOKUP(A10,Structura!A12:L28,12,0) -> 8 | F10: 19 | G10: 41 | H10: 200 | I10: =(G10*E10*F10)+H10 -> 6432
A11: 8 | B11: Sighinas | C11: Razvan | D11: =VLOOKUP(B11,Table4[[Nume]:[Post]],10,0) -> Deputy CEO & Chief Information Officer | E11: =VLOOKUP(A11,Structura!A13:L29,12,0) -> 8 | F11: 20 | G11: 39 | H11: 150 | I11: =(G11*E11*F11)+H11 -> 6390
A12: 9 | B12: Ilie | C12: Florin | D12: =VLOOKUP(B12,Table4[[Nume]:[Post]],10,0) -> Deputy CEO & Head of Wholesale Banking | E12: =VLOOKUP(A12,Structura!A14:L30,12,0) -> 8 | F12: 21 | G12: 38 | H12: 600 | I12: =(G12*E12*F12)+H12 -> 6984
A13: 10 | B13: Popa | C13: Denis | D13: =VLOOKUP(B13,Table4[[Nume]:[Post]],10,0) -> Operating Officer | E13: =VLOOKUP(A13,Structura!A15:L31,12,0) -> 8 | F13: 21 | G13: 35 | H13: 420 | I13: =(G13*E13*F13)+H13 -> 6300
A14: 11 | B14: Sima | C14: Ioana | D14: =VLOOKUP(B14,Table4[[Nume]:[Post]],10,0) -> Operating Officer | E14: =VLOOKUP(A14,Structura!A16:L32,12,0) -> 8 | F14: 20 | G14: 32 | H14: 150 | I14: =(G14*E14*F14)+H14 -> 5270
A15: 12 | B15: Mihalache | C15: Daniel | D15: =VLOOKUP(B15,Table4[[Nume]:[Post]],10,0) -> Relationship Manager Corporate | E15: =VLOOKUP(A15,Structura!A17:L33,12,0) -> 8 | F15: 18 | G15: 30 | H15: 150 | I15: =(G15*E15*F15)+H15 -> 4470
A16: 13 | B16: Vladimir | C16: Ioan | D16: =VLOOKUP(B16,Table4[[Nume]:[Post]],10,0) -> Relationship Manager Corporate | E16: =VLOOKUP(A16,Structura!A18:L34,12,0) -> 8 | F16: 19 | G16: 33 | H16: 200 | I16: =(G16*E16*F16)+H16 -> 5216
A17: 14 | B17: Vlad | C17: Mihai | D17: =VLOOKUP(B17,Table4[[Nume]:[Post]],10,0) -> Specialist Contract Center | E17: =VLOOKUP(A17,Structura!A19:L35,12,0) -> 8 | F17: 21 | G17: 34 | H17: 300 | I17: =(G17*E17*F17)+H17 -> 6012
A18: 15 | B18: Corpa | C18: Andreea | D18: =VLOOKUP(B18,Table4[[Nume]:[Post]],10,0) -> Specialist Contract Center | E18: =VLOOKUP(A18,Structura!A20:L36,12,0) -> 8 | F18: 18 | G18: 29 | H18: 205 | I18: =(G18*E18*F18)+H18 -> 4381
A19: 16 | B19: Ioan | C19: Vasile | D19: =VLOOKUP(B19,Table4[[Nume]:[Post]],10,0) -> Call Center Officer | E19: =VLOOKUP(A19,Structura!A21:L37,12,0) -> 8 | F19: 17 | G19: 28 | H19: 200 | I19: =(G19*E19*F19)+H19 -> 4008
A20: 17 | B20: Ionescu | C20: Diana | D20: =VLOOKUP(B20,Table4[[Nume]:[Post]],10,0) -> Call Center Officer | E20: =VLOOKUP(A20,Structura!A22:L38,12,0) -> 8 | F20: 21 | G20: 28 | H20: 150 | I20: =(G20*E20*F20)+H20 -> 4854
A23: Nume agent | D23: Corpa
A24: Salariu agent | D24: =VLOOKUP(D23,B4:I20,8,0) -> 4381
A25: Salariu mediu | D25: =AVERAGE(I4:I20) -> 6319.3529
A26: Comparatie salariu agentului fata de medie | D26: =IF(D24>D25,"Mai mare","Mai mic") -> Mai mic
A27: Cel mai mare salariu | D27: =MAX(SalariuNet) -> 11080
A28: cel mai mic salariu | D28: =MIN(I4:I20) -> 4008

Sheet Subtotal tabel credite
C1: Subtotal tabel credite | L1: Home
A3: Agent | B3: Tip credit | C3: Valoare (lei) | D3: Data intocmire credit | E3: Data rambursare credit | F3: Status
A4: Andreea Corpa | B4: Credit auto | C4: 20000 | D4: 42785 | E4: 45736 | F4: =IF(E4>TODAY(),"In curs de achitare","Achitat") -> Achitat
A5: Andreea Corpa | B5: Credit de nevoie personale | C5: 6500 | D5: 43875 | E5: 44483 | F5: =IF(E5>TODAY(),"In curs de achitare","Achitat") -> Achitat
A6: Andreea Corpa Total | C6: =SUBTOTAL(9,C4:C5) -> 26500
A7: Bogdan Boteanu | B7: Prima casa | C7: 200000 | D7: 39428 | E7: 50386 | F7: =IF(E7>TODAY(),"In curs de achitare","Achitat") -> In curs de achitare
A8: Bogdan Boteanu | B8: Credit Imobiliar | C8: 150000 | D8: 38632 | E8: 43838 | F8: =IF(E8>TODAY(),"In curs de achitare","Achitat") -> Achitat
A9: Bogdan Boteanu Total | C9: =SUBTOTAL(9,C7:C8) -> 350000
A10: Daniel Mihalache | B10: Credit auto | C10: 75000 | D10: 43352 | E10: 45542 | F10: =IF(E10>TODAY(),"In curs de achitare","Achitat") -> Achitat
A11: Daniel Mihalache Total | C11: =SUBTOTAL(9,C10:C10) -> 75000
A12: Denis Popa | B12: Credit auto | C12: 50000 | D12: 42370 | E12: 43868 | F12: =IF(E12>TODAY(),"In curs de achitare","Achitat") -> Achitat
A13: Denis Popa | B13: Credit de nevoie personale | C13: 5000 | D13: 43942 | E13: 44490 | F13: =IF(E13>TODAY(),"In curs de achitare","Achitat") -> Achitat
A14: Denis Popa | B14: Credit de nevoie personale | C14: 15000 | D14: 43297 | E14: 43693 | F14: =IF(E14>TODAY(),"In curs de achitare","Achitat") -> Achitat
A15: Denis Popa | B15: Prima casa | C15: 120000 | D15: 39884 | E15: 50872 | F15: =IF(E15>TODAY(),"In curs de achitare","Achitat") -> In curs de achitare
A16: Denis Popa Total | C16: =SUBTOTAL(9,C12:C15) -> 190000
A17: Florin Ilie | B17: Credit Imobiliar | C17: 80000 | D17: 36558 | E17: 43628 | F17: =IF(E17>TODAY(),"In curs de achitare","Achitat") -> Achitat
A18: Florin Ilie | B18: Prima casa | C18: 90000 | D18: 42796 | E18: 51323 | F18: =IF(E18>TODAY(),"In curs de achitare","Achitat") -> In curs de achitare
A19: Florin Ilie | B19: Credit de nevoie personale | C19: 10000 | D19: 42042 | E19: 42407 | F19: =IF(E19>TODAY(),"In curs de achitare","Achitat") -> Achitat
A20: Florin Ilie Total | C20: =SUBTOTAL(9,C17:C19) -> 180000
A21: Ioan Vladimir | B21: Credit auto | C21: 20000 | D21: 42737 | E21: 44257 | F21: =IF(E21>TODAY(),"In curs de achitare","Achitat") -> Achitat
A22: Ioan Vladimir Total | C22: =SUBTOTAL(9,C21:C21) -> 20000
A23: Ioana Sima | B23: Credit de nevoie personale | C23: 10000 | D23: 43819 | E23: 44185 | F23: =IF(E23>TODAY(),"In curs de achitare","Achitat") -> Achitat
A24: Ioana Sima | B24: Credit Imobiliar | C24: 90000 | D24: 40395 | E24: 49432 | F24: =IF(E24>TODAY(),"In curs de achitare","Achitat") -> In curs de achitare
A25: Ioana Sima Total | C25: =SUBTOTAL(9,C23:C24) -> 100000
A26: Maria-Cristina Matei | B26: Credit auto | C26: 35000 | D26: 41461 | E26: 43711 | F26: =IF(E26>TODAY(),"In curs de achitare","Achitat") -> Achitat
A27: Maria-Cristina Matei | B27: Credit auto | C27: 75000 | D27: 41162 | E27: 43089 | F27: =IF(E27>TODAY(),"In curs de achitare","Achitat") -> Achitat
A28: Maria-Cristina Matei | B28: Credit de nevoie personale | C28: 7500 | D28: 41011 | E28: 41376 | F28: =IF(E28>TODAY(),"In curs de achitare","Achitat") -> Achitat
A29: Maria-Cristina Matei Total | C29: =SUBTOTAL(9,C26:C28) -> 117500
A30: Mihai Vlad | B30: Credit auto | C30: 45000 | D30: 42262 | E30: 44088 | F30: =IF(E30>TODAY(),"In curs de achitare","Achitat") -> Achitat
A31: Mihai Vlad | B31: Prima casa | C31: 80000 | D31: 36819 | E31: 45702 | F31: =IF(E31>TODAY(),"In curs de achitare","Achitat") -> Achitat
A32: Mihai Vlad Total | C32: =SUBTOTAL(9,C30:C31) -> 125000
A33: Sergiu Silva | B33: Credit de nevoie personale | C33: 15000 | D33: 43203 | E33: 43966 | F33: =IF(E33>TODAY(),"In curs de achitare","Achitat") -> Achitat
A34: Sergiu Silva | B34: Prima casa | C34: 250000 | D34: 43898 | E34: 51419 | F34: =IF(E34>TODAY(),"In curs de achitare","Achitat") -> In curs de achitare
A35: Sergiu Silva Total | C35: =SUBTOTAL(9,C33:C34) -> 265000
A36: Vlad Octav | B36: Credit de nevoie personale | C36: 12000 | D36: 44124 | E36: 44489 | F36: =IF(E36>TODAY(),"In curs de achitare","Achitat") -> Achitat
A37: Vlad Octav Total | C37: =SUBTOTAL(9,C36:C36) -> 12000
A38: Grand Total | C38: =SUBTOTAL(9,C4:C36) -> 1461000

Sheet Import clienti txt
F1: Import clienti din Text Document
A3: Nume client | B3: Prenume client | C3: CNP client | D3: Adresa client | E3: Telefon | F3: Mail | G3: Tip Credit | H3: Numar ani credit | I3: Valoare credit (RON) | J3: Data intocmire credit | K3: Ora | L3: Agent | M3: Feedback client | N3: Cod Client
A4: Popescu | B4: Mihai | C4: 1931212329022 | D4: Sibiu str. Vasile Milea nr13 | E4: 751793004 | F4: popescu.mihai@yahoo.com | G4: Prima casa | H4: 30 | I4: 200000 | J4: 39428 | K4: 0.53263889 | L4: Bogdan Boteanu | M4: Partial multumit | N4: C101
A5: Ionescu | B5: Diana | C5: 2950713322028 | D5: Sibiu str. Postop bl5 ap5 | E5: 763704432 | F5: dianamariaionescu@gmail.com | G5: Credit Imobiliar | H5: 14 | I5: 150000 | J5: 38632 | K5: 0.65277778 | L5: Bogdan Boteanu | M5: Multumit | N5: C102
A6: Clopa | B6: Maria | C6: 2991026399122 | D6: Alba Iulia str Ghergeni nr18 | E6: 754704232 | F6: mariaclopa@yahoo.com | G6: Credit de nevoi personale | H6: 2 | I6: 15000 | J6: 43203 | K6: 0.48541667 | L6: Sergiu Silva | M6: Dezamagit | N6: C103
A7: Stefan | B7: Vasile | C7: 1951112721032 | D7: Sibiu str. Lazaret bl28 ap6 | E7: 732753622 | F7: stefn_vasile@yahoo.com | G7: Credit auto | H7: 6 | I7: 35000 | J7: 41461 | K7: 0.63888889 | L7: Maria-Cristina Matei | M7: Multumit | N7: C104
A8: Gheorge | B8: Ion | C8: 1900402329526 | D8: Sibiu str. Popesco nr340 | E8: 721343552 | F8: ionmariangheorge@yahoo.com | G8: Credit auto | H8: 4 | I8: 50000 | J8: 42370 | K8: 0.39097222 | L8: Denis Popa | M8: Multumit | N8: C105
A9: Alexa | B9: Ioana | C9: 2990312529622 | D9: Sibiu str. Pepe nr.76 | E9: 751793039 | F9: alexa.ioana@yahoo.com | G9: Prima casa | H9: 20 | I9: 250000 | J9: 43898 | K9: 0.46111111 | L9: Sergiu Silva | M9: Multumit | N9: C108
A10: Oprea | B10: Patricia | C10: 2950215329632 | D10: Sibiu str. Omega nr2 | E10: 751794432 | F10: oprea.patricia@yahoo.com | G10: Credit Imobliliar | H10: 19 | I10: 80000 | J10: 36558 | K10: 0.44930556 | L10: Florin Ilie | M10: Multumit | N10: C107
A11: Alexa | B11: Ioana | C11: 2990312529622 | D11: Sibiu str. Pepe nr.76 | E11: 751793039 | F11: alexa.ioana@yahoo.com | G11: Credit de nevoi personale | H11: 1 | I11: 10000 | J11: 43819 | K11: 0.36805556 | L11: Ioana Sima | M11: Multumit | N11: C108
A12: Vasile | B12: Alexandra | C12: 2990320523822 | D12: Medias str. Secundara nr.123 | E12: 753703032 | F12: vasile_alexandra@yahoo.com | G12: Credit auto | H12: 8 | I12: 20000 | J12: 42785 | K12: 0.53472222 | L12: Andreea Corpa | M12: Partial multumit | N12: C109
A13: Vlad | B13: Andrei | C13: 1980612521682 | D13: Sibiu str. Ecuso bl4. ap3 | E13: 751733422 | F13: vlad.andrei@gmail.com | G13: Credit auto | H13: 4 | I13: 45000 | J13: 42262 | K13: 0.57291667 | L13: Mihai Vlad | M13: Multumit | N13: C110
A14: Posca | B14: Darius | C14: 1950812229692 | D14: Sibiu str. Graului nr29 | E14: 721603032 | F14: poscadarius12@gmail.com | G14: Prima casa | H14: 23 | I14: 90000 | J14: 42796 | K14: 0.64444444 | L14: Florin Ilie | M14: Multumit | N14: C119
A15: Popa | B15: George | C15: 1970112629662 | D15: Sibiu str. Sica nr21 | E15: 756523332 | F15: popaghoerghe20@yahoo.ro | G15: Credit de nevoi personale | H15: 1 | I15: 5000 | J15: 43942 | K15: 0.45069444 | L15: Denis Popa | M15: Multumit | N15: C112
... A26: Stefan | B26: Vasile | C26: 1951112721032 | D26: Sibiu str. Lazaret bl28 ap6 | E26: 751793039 | F26: stefn_vasile@yahoo.com | G26: Credit de nevoi personale | H26: 1 | I26: 10000 | J26: 42407 | K26: 0.63125 | L26: Florin Ilie | M26: Partial multumit | N26: C104

Sheet Tableta Pivot
C1: Tableta pivot | K1: Home
A3: Mail | B3: (All)
A4: Telefon | B4: (All)
A6: Sum of Valoare credit (RON) | B6: Column Labels
A7: Row Labels | B7: Credit auto | C7: Credit de nevoi personale | D7: Credit Imobiliar | E7: Credit Imobliliar | F7: Prima casa | G7: Grand Total
A8: Alexa | C8: 16500 | F8: 250000 | G8: 266500
A9: C108 | C9: 16500 | F9: 250000 | G9: 266500
A10: 43819 | C10: 10000 | G10: 10000
A11: 43875 | C11: 6500 | G11: 6500
A12: 43898 | F12: 250000 | G12: 250000
A13: Clopa | C13: 15000 | G13: 15000
A14: C103 | C14: 15000 | G14: 15000
A15: 43203 | C15: 15000 | G15: 15000
A16: Gheorge | B16: 50000 | G16: 50000
A17: C105 | B17: 50000 | G17: 50000
A18: 42370 | B18: 50000 | G18: 50000
A19: Goca | F19: 120000 | G19: 120000
A20: C117 | F20: 120000 | G20: 120000
A21: 39884 | F21: 120000 | G21: 120000
A22: Ionescu | D22: 150000 | F22: 80000 | G22: 230000
A23: C102 | D23: 150000 | F23: 80000 | G23: 230000
A24: 36819 | F24: 80000 | G24: 80000
A25: 38632 | D25: 150000 | G25: 150000
A26: Jopa | C26: 7500 | G26: 7500
A27: C120 | C27: 7500 | G27: 7500
A28: 41011 | C28: 7500 | G28: 7500
A29: Marica | B29: 75000 | G29: 75000
A30: C113 | B30: 75000 | G30: 75000
A31: 43352 | B31: 75000 | G31: 75000
A32: Oprea | E32: 80000 | G32: 80000
A33: C107 | E33: 80000 | G33: 80000
A34: 36558 | E34: 80000 | G34: 80000
A35: Pircu | C35: 12000 | G35: 12000
A36: C115 | C36: 12000 | G36: 12000
A37: 44489 | C37: 12000 | G37: 12000
A38: Popa | C38: 5000 | G38: 5000
A39: C112 | C39: 5000 | G39: 5000
A40: 43942 | C40: 5000 | G40: 5000
A41: Popescu | B41: 20000 | F41: 200000 | G41: 220000
A42: C101 | B42: 20000 | F42: 200000 | G42: 220000
...
